Workbook

Sheet Guide
A1: Break-even transport engine
A2: Purpose | B2: Calculate the loaded-km rate, utilisation and revenue required for break-even and target EBIT margin.
A3: Model design | B3: Separates variable €/km costs from fixed annual costs, driver costs, structural overhead and optional platform/admin cost.
A4: Improvement vs original sheet | B4: Driver taxes are calculated from salary using the tax percentage instead of a hardcoded daily tax value.
A5: Key output | B5: Break-even price per loaded km, required price for target margin, break-even loaded km, break-even utilisation, EBIT and safety margin.
A6: How to use | B6: Edit assumptions in Inputs. Review results in Engine. Use Sensitivity to test price and load factor.
A7: Note | B7: Values are prefilled from the uploaded Vehicle1 and Vehicle2 sheets and can be overwritten.
A9: Added in this version
A10: Vehicle Classes | B10: New editable assumption table covering van, rigid trucks, 40t/44t articulated vehicles and EMS/high-capacity 60t scenario.
A11: Sensitivity | B11: New load-capability section compares break-even EUR/loaded-km and EUR/tonne-km by vehicle class.
A12: Payload utilisation matrix | B12: Shows how underloading increases break-even EUR/tonne-km for the same truck type.
A13: Regulatory caution | B13: 40t/44t and EMS/high-capacity assumptions depend on the relevant country, route, axle configuration, and permit regime.
A14: Sources | B14: Public source URLs are included on the Vehicle Classes sheet.
A15: Model status | B15: Truck-class cost values are modelling assumptions and should be replaced with actual fleet quotes when available.
A16: Daily km driver | B16: The model now asks for Daily km in Inputs row 2. Annual total km is calculated in Inputs row 28 as Daily km × Operating days, and the Engine uses that calculated annual value.
A17: Pricing Scenarios | B17: Customer rate is now calculated after break-even as break-even price × selected markup. It is no longer entered in Inputs.
A18: Pricing caution | B18: Markup over break-even and EBIT margin are not identical. The sheet includes a cross-check for the markup required to reach the target EBIT margin.
A19: Company & Tax Profile | B19: New layer for company type, VAT, business tax, and after-tax profitability.
A20: Tax logic | B20: The engine remains pre-tax. VAT is shown separately and is not treated as revenue or profit.
A21: Invoice rate | B21: Pricing Scenarios now shows both customer rate excl. VAT and invoice rate incl. VAT.
... A28: Validation warning | B28: Country-level rates are for modelling and must be validated with local tax/legal/accounting advice before commercial usage.

Sheet Inputs
A1: Input | B1: Unit | C1: Long Distance 40t | D1: Regional 40t | E1: Comment
A2: Daily km | B2: km/day | C2: 495.18389 | D2: 421.50538 | E2: Editable daily distance; annual total km is calculated as daily km × operating days
A3: Operating days | B3: days/year | C3: 228.4 | D3: 232.5 | E3: Vehicle operating days
A4: Working days | B4: days/year | C4: 215.2 | D4: 214.6 | E4: Used for driver allowance calculation
A5: Annual working hours | B5: hours/year | C5: 2123 | D5: 2058 | E5: Available driver working hours
A6: Average speed | B6: km/h | C6: 63.9 | D6: 62.5 | E6: Used to estimate driving hours
A7: Loaded ratio | B7: % loaded km | C7: 0.853 | D7: 0.805 | E7: Revenue km divided by total km
A8: Capacity utilisation | B8: % capacity | C8: 0.868 | D8: 0.939 | E8: Payload/capacity usage; diagnostic only
A9: Waiting/loading/unloading time | B9: hours/day | C9: 3.3833333 | D9: 3.4 | E9: Converted from original waiting-time text
A10: Fuel consumption | B10: L/100km | C10: 34.2 | D10: 33.8 | E10: Average consumption
A11: Fuel price excl. VAT | B11: EUR/L | C11: 1.2655246 | D11: 1.2655246 | E11: Original formula 5.91 / 4.67
A12: Tyres annual cost | B12: EUR/year | C12: 3098 | D12: 3101
A13: Maintenance annual cost | B13: EUR/year | C13: 8221 | D13: 7278
A14: Road fees annual cost | B14: EUR/year | C14: 8090 | D14: 5805
A15: Tractor ownership annual cost | B15: EUR/year | C15: 10793 | D15: 10934
A16: Trailer ownership annual cost | B16: EUR/year | C16: 3208 | D16: 3551
A17: Vehicle insurance annual | B17: EUR/year | C17: 2198 | D17: 2598
A18: Cargo insurance annual | B18: EUR/year | C18: 477 | D18: 411
A19: Vehicle taxes annual | B19: EUR/year | C19: ='Company & Tax Profile'!$B$16 | D19: ='Company & Tax Profile'!$B$16 | E19: Linked from Company & Tax Profile; replace country default with vehicle-specific tax if needed.
A20: Monthly driver salary | B20: EUR/month | C20: 2348.72 | D20: 2182.15
A21: Employer tax rate on salary | B21: % | C21: ='Company & Tax Profile'!$B$14 | D21: ='Company & Tax Profile'!$B$14 | E21: Linked from Company & Tax Profile employer payroll contribution rate.
A22: Travel allowance per working day | B22: EUR/day | C22: 38.36 | D22: 16.53
A23: Drivers per vehicle | B23: count | C23: 1.064 | D23: 1.085
A24: Structural overhead annual | B24: EUR/year | C24: 17886 | D24: 17820
A25: Commercial/admin overhead annual cost | B25: EUR/year | C25: 0 | D25: 0 | E25: Optional general commercial overhead, set to zero by default
A26: Target EBIT margin | B26: % revenue | C26: 0.1 | D26: 0.1 | E26: Required margin on revenue
A27: Customer pricing source | B27: sheet | C27: Pricing Scenarios | D27: Pricing Scenarios | E27: Customer rate is calculated after break-even; it is no longer an input assumption.
A28: Computed annual total km | B28: km/year | C28: =C2*C3 | D28: =D2*D3 | E28: Formula: daily km × operating days

Sheet Engine
A1: Metric | B1: Unit | C1: Long Distance 40t | D1: Regional 40t | E1: Formula logic
A2: Input links
A3: Annual total km | B3: km/year | C3: =Inputs!C28 | D3: =Inputs!D28 | E3: Computed from daily km × operating days
A4: Operating days | B4: days/year | C4: =Inputs!C3 | D4: =Inputs!D3 | E4: Inputs
A5: Working days | B5: days/year | C5: =Inputs!C4 | D5: =Inputs!D4 | E5: Inputs
A6: Annual working hours | B6: hours/year | C6: =Inputs!C5 | D6: =Inputs!D5 | E6: Inputs
A7: Average speed | B7: km/h | C7: =Inputs!C6 | D7: =Inputs!D6 | E7: Inputs
A8: Loaded ratio | B8: % loaded km | C8: =Inputs!C7 | D8: =Inputs!D7 | E8: Inputs
A9: Capacity utilisation | B9: % capacity | C9: =Inputs!C8 | D9: =Inputs!D8 | E9: Diagnostic
A10: Waiting/loading/unloading time | B10: hours/day | C10: =Inputs!C9 | D10: =Inputs!D9 | E10: Inputs
A11: Fuel consumption | B11: L/100km | C11: =Inputs!C10 | D11: =Inputs!D10 | E11: Inputs
A12: Fuel price excl. VAT | B12: EUR/L | C12: =Inputs!C11 | D12: =Inputs!D11 | E12: Inputs
A13: Tyres annual cost | B13: EUR/year | C13: =Inputs!C12 | D13: =Inputs!D12 | E13: Inputs
A14: Maintenance annual cost | B14: EUR/year | C14: =Inputs!C13 | D14: =Inputs!D13 | E14: Inputs
A15: Road fees annual cost | B15: EUR/year | C15: =Inputs!C14 | D15: =Inputs!D14 | E15: Inputs
... A27: Target EBIT margin | B27: % revenue | C27: =Inputs!C26 | D27: =Inputs!D26 | E27: Inputs
A28: Selected customer rate per loaded km | B28: EUR/loaded km | C28: ='Pricing Scenarios'!C18 | D28: ='Pricing Scenarios'!D18 | E28: Calculated in Pricing Scenarios after break-even price
A30: Operational outputs
A31: Loaded revenue km | B31: km/year | C31: =IFERROR(C3*C8,0) | D31: =IFERROR(D3*D8,0) | E31: Annual total km × loaded ratio
A32: Empty/non-revenue km | B32: km/year | C32: =IFERROR(C3-C31,0) | D32: =IFERROR(D3-D31,0) | E32: Annual total km - loaded km
A33: Driving hours | B33: hours/year | C33: =IFERROR(C3/C7,0) | D33: =IFERROR(D3/D7,0) | E33: Annual total km / average speed
A34: Waiting/loading/unloading hours | B34: hours/year | C34: =IFERROR(C4*C10,0) | D34: =IFERROR(D4*D10,0) | E34: Operating days × waiting time/day
A35: Total activity hours | B35: hours/year | C35: =IFERROR(C33+C34,0) | D35: =IFERROR(D33+D34,0) | E35: Driving hours + waiting/loading/unloading hours
A37: Variable cost block
A38: Fuel cost | B38: EUR/total km | C38: =IFERROR(C11/100*C12,0) | D38: =IFERROR(D11/100*D12,0) | E38: Fuel consumption / 100 × fuel price
A39: Tyres cost | B39: EUR/total km | C39: =IFERROR(C13/C3,0) | D39: =IFERROR(D13/D3,0) | E39: Annual tyres / annual total km
A40: Maintenance cost | B40: EUR/total km | C40: =IFERROR(C14/C3,0) | D40: =IFERROR(D14/D3,0) | E40: Annual maintenance / annual total km
A41: Road fees cost | B41: EUR/total km | C41: =IFERROR(C15/C3,0) | D41: =IFERROR(D15/D3,0) | E41: Annual road fees / annual total km
A42: Variable operating cost | B42: EUR/total km | C42: =SUM(C38:C41) | D42: =SUM(D38:D41) | E42: Fuel + tyres + maintenance + road fees
A43: Variable operating cost | B43: EUR/loaded km | C43: =IFERROR(C42/C8,0) | D43: =IFERROR(D42/D8,0) | E43: Variable cost per total km / loaded ratio
A44: Annual variable operating cost | B44: EUR/year | C44: =IFERROR(C42*C3,0) | D44: =IFERROR(D42*D3,0) | E44: Variable cost per total km × annual total km
A46: Driver cost block
A47: Salary incl. employer taxes | B47: EUR/year | C47: =IFERROR(C21*12*C24*(1+C22),0) | D47: =IFERROR(D21*12*D24*(1+D22),0) | E47: Monthly salary × 12 × drivers × (1 + tax rate)
A48: Travel allowance | B48: EUR/year | C48: =IFERROR(C23*C5*C24,0) | D48: =IFERROR(D23*D5*D24,0) | E48: Allowance/day × working days × drivers
A49: Total driver cost | B49: EUR/year | C49: =SUM(C47:C48) | D49: =SUM(D47:D48) | E49: Salary incl. taxes + allowance
A50: Driver cost per activity hour | B50: EUR/hour | C50: =IFERROR(C49/C35,0) | D50: =IFERROR(D49/D35,0) | E50: Total driver cost / activity hours
A51: Driver cost per loaded km | B51: EUR/loaded km | C51: =IFERROR(C49/C31,0) | D51: =IFERROR(D49/D31,0) | E51: Total driver cost / loaded km
A53: Fixed cost block
A54: Vehicle fixed cost | B54: EUR/year | C54: =SUM(C16:C20) | D54: =SUM(D16:D20) | E54: Tractor + trailer + insurance + taxes
A55: Structural/admin fixed cost | B55: EUR/year | C55: =SUM(C25:C26) | D55: =SUM(D25:D26) | E55: Structural overhead + commercial/admin overhead
...

Sheet Sensitivity
A1: Break-even sensitivity
A2: Selected profile | B2: Long Distance 40t | J2: Selected column | K2: =MATCH($B$2,Engine!$C$1:$D$1,0)
J3: Annual total km | K3: =INDEX(Engine!$C$3:$D$3,1,$K$2)
A4: Rate/load factor EBIT matrix | J4: Variable €/total km | K4: =INDEX(Engine!$C$42:$D$42,1,$K$2)
A5: Load factor \ Rate | B5: 1.2 | C5: 1.4 | D5: 1.6 | E5: 1.8 | F5: 2 | G5: 2.2 | H5: 2.4 | J5: Fixed incl driver | K5: =INDEX(Engine!$C$57:$D$57,1,$K$2)
A6: 0.65 | B6: =B$5*$K$3*$A6-($K$5+$K$4*$K$3) | C6: =C$5*$K$3*$A6-($K$5+$K$4*$K$3) | D6: =D$5*$K$3*$A6-($K$5+$K$4*$K$3) | E6: =E$5*$K$3*$A6-($K$5+$K$4*$K$3) | F6: =F$5*$K$3*$A6-($K$5+$K$4*$K$3) | G6: =G$5*$K$3*$A6-($K$5+$K$4*$K$3) | H6: =H$5*$K$3*$A6-($K$5+$K$4*$K$3) | J6: Loaded ratio | K6: =INDEX(Engine!$C$8:$D$8,1,$K$2)
A7: 0.7 | B7: =B$5*$K$3*$A7-($K$5+$K$4*$K$3) | C7: =C$5*$K$3*$A7-($K$5+$K$4*$K$3) | D7: =D$5*$K$3*$A7-($K$5+$K$4*$K$3) | E7: =E$5*$K$3*$A7-($K$5+$K$4*$K$3) | F7: =F$5*$K$3*$A7-($K$5+$K$4*$K$3) | G7: =G$5*$K$3*$A7-($K$5+$K$4*$K$3) | H7: =H$5*$K$3*$A7-($K$5+$K$4*$K$3) | J7: Current BE price | K7: =INDEX(Engine!$C$62:$D$62,1,$K$2)
A8: 0.75 | B8: =B$5*$K$3*$A8-($K$5+$K$4*$K$3) | C8: =C$5*$K$3*$A8-($K$5+$K$4*$K$3) | D8: =D$5*$K$3*$A8-($K$5+$K$4*$K$3) | E8: =E$5*$K$3*$A8-($K$5+$K$4*$K$3) | F8: =F$5*$K$3*$A8-($K$5+$K$4*$K$3) | G8: =G$5*$K$3*$A8-($K$5+$K$4*$K$3) | H8: =H$5*$K$3*$A8-($K$5+$K$4*$K$3) | J8: Target margin price | K8: =INDEX(Engine!$C$63:$D$63,1,$K$2)
A9: 0.8 | B9: =B$5*$K$3*$A9-($K$5+$K$4*$K$3) | C9: =C$5*$K$3*$A9-($K$5+$K$4*$K$3) | D9: =D$5*$K$3*$A9-($K$5+$K$4*$K$3) | E9: =E$5*$K$3*$A9-($K$5+$K$4*$K$3) | F9: =F$5*$K$3*$A9-($K$5+$K$4*$K$3) | G9: =G$5*$K$3*$A9-($K$5+$K$4*$K$3) | H9: =H$5*$K$3*$A9-($K$5+$K$4*$K$3) | J9: Selected customer rate | K9: =INDEX(Engine!$C$28:$D$28,1,$K$2)
A10: 0.85 | B10: =B$5*$K$3*$A10-($K$5+$K$4*$K$3) | C10: =C$5*$K$3*$A10-($K$5+$K$4*$K$3) | D10: =D$5*$K$3*$A10-($K$5+$K$4*$K$3) | E10: =E$5*$K$3*$A10-($K$5+$K$4*$K$3) | F10: =F$5*$K$3*$A10-($K$5+$K$4*$K$3) | G10: =G$5*$K$3*$A10-($K$5+$K$4*$K$3) | H10: =H$5*$K$3*$A10-($K$5+$K$4*$K$3) | J10: EBIT at selected rate | K10: =INDEX(Engine!$C$65:$D$65,1,$K$2)
A11: 0.9 | B11: =B$5*$K$3*$A11-($K$5+$K$4*$K$3) | C11: =C$5*$K$3*$A11-($K$5+$K$4*$K$3) | D11: =D$5*$K$3*$A11-($K$5+$K$4*$K$3) | E11: =E$5*$K$3*$A11-($K$5+$K$4*$K$3) | F11: =F$5*$K$3*$A11-($K$5+$K$4*$K$3) | G11: =G$5*$K$3*$A11-($K$5+$K$4*$K$3) | H11: =H$5*$K$3*$A11-($K$5+$K$4*$K$3)
A12: 0.95 | B12: =B$5*$K$3*$A12-($K$5+$K$4*$K$3) | C12: =C$5*$K$3*$A12-($K$5+$K$4*$K$3) | D12: =D$5*$K$3*$A12-($K$5+$K$4*$K$3) | E12: =E$5*$K$3*$A12-($K$5+$K$4*$K$3) | F12: =F$5*$K$3*$A12-($K$5+$K$4*$K$3) | G12: =G$5*$K$3*$A12-($K$5+$K$4*$K$3) | H12: =H$5*$K$3*$A12-($K$5+$K$4*$K$3)
A14: Scenario curve at current loaded ratio
A15: Rate | B15: Long Distance EBIT | C15: Regional EBIT
A16: 1.2 | B16: =$A16*Engine!$C$3*Engine!$C$8-(Engine!$C$57+Engine!$C$42*Engine!$C$3) | C16: =$A16*Engine!$D$3*Engine!$D$8-(Engine!$D$57+Engine!$D$42*Engine!$D$3)
A17: 1.3 | B17: =$A17*Engine!$C$3*Engine!$C$8-(Engine!$C$57+Engine!$C$42*Engine!$C$3) | C17: =$A17*Engine!$D$3*Engine!$D$8-(Engine!$D$57+Engine!$D$42*Engine!$D$3)
A18: 1.4 | B18: =$A18*Engine!$C$3*Engine!$C$8-(Engine!$C$57+Engine!$C$42*Engine!$C$3) | C18: =$A18*Engine!$D$3*Engine!$D$8-(Engine!$D$57+Engine!$D$42*Engine!$D$3)
A19: 1.5 | B19: =$A19*Engine!$C$3*Engine!$C$8-(Engine!$C$57+Engine!$C$42*Engine!$C$3) | C19: =$A19*Engine!$D$3*Engine!$D$8-(Engine!$D$57+Engine!$D$42*Engine!$D$3)
A20: 1.6 | B20: =$A20*Engine!$C$3*Engine!$C$8-(Engine!$C$57+Engine!$C$42*Engine!$C$3) | C20: =$A20*Engine!$D$3*Engine!$D$8-(Engine!$D$57+Engine!$D$42*Engine!$D$3)
A21: 1.7 | B21: =$A21*Engine!$C$3*Engine!$C$8-(Engine!$C$57+Engine!$C$42*Engine!$C$3) | C21: =$A21*Engine!$D$3*Engine!$D$8-(Engine!$D$57+Engine!$D$42*Engine!$D$3)
A22: 1.8 | B22: =$A22*Engine!$C$3*Engine!$C$8-(Engine!$C$57+Engine!$C$42*Engine!$C$3) | C22: =$A22*Engine!$D$3*Engine!$D$8-(Engine!$D$57+Engine!$D$42*Engine!$D$3)
A23: 1.9 | B23: =$A23*Engine!$C$3*Engine!$C$8-(Engine!$C$57+Engine!$C$42*Engine!$C$3) | C23: =$A23*Engine!$D$3*Engine!$D$8-(Engine!$D$57+Engine!$D$42*Engine!$D$3)
A24: 2 | B24: =$A24*Engine!$C$3*Engine!$C$8-(Engine!$C$57+Engine!$C$42*Engine!$C$3) | C24: =$A24*Engine!$D$3*Engine!$D$8-(Engine!$D$57+Engine!$D$42*Engine!$D$3)
A25: 2.1 | B25: =$A25*Engine!$C$3*Engine!$C$8-(Engine!$C$57+Engine!$C$42*Engine!$C$3) | C25: =$A25*Engine!$D$3*Engine!$D$8-(Engine!$D$57+Engine!$D$42*Engine!$D$3)
A26: 2.2 | B26: =$A26*Engine!$C$3*Engine!$C$8-(Engine!$C$57+Engine!$C$42*Engine!$C$3) | C26: =$A26*Engine!$D$3*Engine!$D$8-(Engine!$D$57+Engine!$D$42*Engine!$D$3)
A27: 2.3 | B27: =$A27*Engine!$C$3*Engine!$C$8-(Engine!$C$57+Engine!$C$42*Engine!$C$3) | C27: =$A27*Engine!$D$3*Engine!$D$8-(Engine!$D$57+Engine!$D$42*Engine!$D$3)
A28: 2.4 | B28: =$A28*Engine!$C$3*Engine!$C$8-(Engine!$C$57+Engine!$C$42*Engine!$C$3) | C28: =$A28*Engine!$D$3*Engine!$D$8-(Engine!$D$57+Engine!$D$42*Engine!$D$3)
A31: Load capability sensitivity by vehicle type
A32: This section compares break-even by vehicle capability, from vans to high-capacity trucks. Use EUR/tonne-km when payload is the commercial constraint; use EUR/loaded-km when the truck is sold as a full-truck movement.
A33: Vehicle class | B33: Payload capacity (t) | C33: Effective payload (t) | D33: Loaded km/year | E33: Annual tonne-km | F33: Total annual cost (EUR) | G33: Break-even EUR/loaded km | H33: Break-even EUR/tonne-km | I33: Availability / validation note | J33: Source URL | K33: Data type
A34: ='Vehicle Classes'!A5 | B34: ='Vehicle Classes'!D5 | C34: ='Vehicle Classes'!F5 | D34: ='Vehicle Classes'!I5 | E34: =D34*C34 | F34: ='Vehicle Classes'!R5 | G34: ='Vehicle Classes'!S5 | H34: ='Vehicle Classes'!T5 | I34: ='Vehicle Classes'!U5 | J34: ='Vehicle Classes'!V5 | K34: ='Vehicle Classes'!W5
A35: ='Vehicle Classes'!A6 | B35: ='Vehicle Classes'!D6 | C35: ='Vehicle Classes'!F6 | D35: ='Vehicle Classes'!I6 | E35: =D35*C35 | F35: ='Vehicle Classes'!R6 | G35: ='Vehicle Classes'!S6 | H35: ='Vehicle Classes'!T6 | I35: ='Vehicle Classes'!U6 | J35: ='Vehicle Classes'!V6 | K35: ='Vehicle Classes'!W6
A36: ='Vehicle Classes'!A7 | B36: ='Vehicle Classes'!D7 | C36: ='Vehicle Classes'!F7 | D36: ='Vehicle Classes'!I7 | E36: =D36*C36 | F36: ='Vehicle Classes'!R7 | G36: ='Vehicle Classes'!S7 | H36: ='Vehicle Classes'!T7 | I36: ='Vehicle Classes'!U7 | J36: ='Vehicle Classes'!V7 | K36: ='Vehicle Classes'!W7
A37: ='Vehicle Classes'!A8 | B37: ='Vehicle Classes'!D8 | C37: ='Vehicle Classes'!F8 | D37: ='Vehicle Classes'!I8 | E37: =D37*C37 | F37: ='Vehicle Classes'!R8 | G37: ='Vehicle Classes'!S8 | H37: ='Vehicle Classes'!T8 | I37: ='Vehicle Classes'!U8 | J37: ='Vehicle Classes'!V8 | K37: ='Vehicle Classes'!W8
A38: ='Vehicle Classes'!A9 | B38: ='Vehicle Classes'!D9 | C38: ='Vehicle Classes'!F9 | D38: ='Vehicle Classes'!I9 | E38: =D38*C38 | F38: ='Vehicle Classes'!R9 | G38: ='Vehicle Classes'!S9 | H38: ='Vehicle Classes'!T9 | I38: ='Vehicle Classes'!U9 | J38: ='Vehicle Classes'!V9 | K38: ='Vehicle Classes'!W9
A39: ='Vehicle Classes'!A10 | B39: ='Vehicle Classes'!D10 | C39: ='Vehicle Classes'!F10 | D39: ='Vehicle Classes'!I10 | E39: =D39*C39 | F39: ='Vehicle Classes'!R10 | G39: ='Vehicle Classes'!S10 | H39: ='Vehicle Classes'!T10 | I39: ='Vehicle Classes'!U10 | J39: ='Vehicle Classes'!V10 | K39: ='Vehicle Classes'!W10
A40: ='Vehicle Classes'!A11 | B40: ='Vehicle Classes'!D11 | C40: ='Vehicle Classes'!F11 | D40: ='Vehicle Classes'!I11 | E40: =D40*C40 | F40: ='Vehicle Classes'!R11 | G40: ='Vehicle Classes'!S11 | H40: ='Vehicle Classes'!T11 | I40: ='Vehicle Classes'!U11 | J40: ='Vehicle Classes'!V11 | K40: ='Vehicle Classes'!W11
A41: ='Vehicle Classes'!A12 | B41: ='Vehicle Classes'!D12 | C41: ='Vehicle Classes'!F12 | D41: ='Vehicle Classes'!I12 | E41: =D41*C41 | F41: ='Vehicle Classes'!R12 | G41: ='Vehicle Classes'!S12 | H41: ='Vehicle Classes'!T12 | I41: ='Vehicle Classes'!U12 | J41: ='Vehicle Classes'!V12 | K41: ='Vehicle Classes'!W12
A42: ='Vehicle Classes'!A13 | B42: ='Vehicle Classes'!D13 | C42: ='Vehicle Classes'!F13 | D42: ='Vehicle Classes'!I13 | E42: =D42*C42 | F42: ='Vehicle Classes'!R13 | G42: ='Vehicle Classes'!S13 | H42: ='Vehicle Classes'!T13 | I42: ='Vehicle Classes'!U13 | J42: ='Vehicle Classes'!V13 | K42: ='Vehicle Classes'!W13
A45: Payload utilisation matrix - break-even EUR per tonne-km | I45: How to read
...

Sheet Vehicle Classes
A1: Vehicle capability assumptions for break-even sensitivity
A2: Blue numbers are editable assumptions; formula cells calculate effective payload, loaded km, annual cost and break-even price. Validate payload and legal access for actual countries/routes before using commercially.
A4: Vehicle class | B4: Capability band | C4: GVW (t) | D4: Payload capacity (t) | E4: Base payload utilisation | F4: Effective payload (t) | G4: Annual total km | H4: Loaded ratio | I4: Loaded km | J4: Fuel L/100km | K4: Fuel price (EUR/L) | L4: Fuel EUR/km | M4: Non-fuel variable EUR/km | N4: Variable cost annual (EUR) | O4: Driver annual cost (EUR) | P4: Fixed vehicle annual (EUR) | Q4: Structural overhead annual (EUR) | R4: Total annual cost (EUR) | S4: Break-even EUR/loaded km | T4: Break-even EUR/tonne-km | U4: Availability / validation note | V4: Source URL | W4: Input/data type
A5: Small van | B5: Urban / light delivery | C5: 3.5 | D5: 1.2 | E5: 0.75 | F5: =D5*E5 | G5: 45000 | H5: 0.7 | I5: =G5*H5 | J5: 9.5 | K5: ='Inputs'!$C$11 | L5: =J5/100*K5 | M5: 0.1 | N5: =(L5+M5)*G5 | O5: 32000 | P5: 12000 | Q5: 6000 | R5: =N5+O5+P5+Q5 | S5: =IFERROR(R5/I5,"") | T5: =IFERROR(R5/(I5*F5),"") | U5: Model assumption; validate payload against actual van spec | V5: https://climate.ec.europa.eu/system/files/2017-03/hdv_lightweighting_en.pdf | W5: Editable
A6: Large van 3.5t | B6: Van / courier | C6: 3.5 | D6: 2 | E6: 0.75 | F6: =D6*E6 | G6: 65000 | H6: 0.72 | I6: =G6*H6 | J6: 12 | K6: ='Inputs'!$C$11 | L6: =J6/100*K6 | M6: 0.14 | N6: =(L6+M6)*G6 | O6: 34000 | P6: 16000 | Q6: 7000 | R6: =N6+O6+P6+Q6 | S6: =IFERROR(R6/I6,"") | T6: =IFERROR(R6/(I6*F6),"") | U6: 3.5t GVW large van; payload can reach about 2t depending on body/spec | V6: https://climate.ec.europa.eu/system/files/2017-03/hdv_lightweighting_en.pdf | W6: Editable
A7: Light truck 7.5t | B7: Small rigid | C7: 7.5 | D7: 3.5 | E7: 0.8 | F7: =D7*E7 | G7: 75000 | H7: 0.75 | I7: =G7*H7 | J7: 16 | K7: ='Inputs'!$C$11 | L7: =J7/100*K7 | M7: 0.2 | N7: =(L7+M7)*G7 | O7: 40000 | P7: 25000 | Q7: 10000 | R7: =N7+O7+P7+Q7 | S7: =IFERROR(R7/I7,"") | T7: =IFERROR(R7/(I7*F7),"") | U7: Operational class assumption; validate by vehicle body and national rules | W7: Editable
A8: Medium rigid 12t | B8: Rigid truck | C8: 12 | D8: 6 | E8: 0.82 | F8: =D8*E8 | G8: 80000 | H8: 0.78 | I8: =G8*H8 | J8: 22 | K8: ='Inputs'!$C$11 | L8: =J8/100*K8 | M8: 0.27 | N8: =(L8+M8)*G8 | O8: 43000 | P8: 38000 | Q8: 12000 | R8: =N8+O8+P8+Q8 | S8: =IFERROR(R8/I8,"") | T8: =IFERROR(R8/(I8*F8),"") | U8: Operational class assumption; payload depends on body and axle setup | W8: Editable
A9: Rigid truck 18t | B9: Rigid truck | C9: 18 | D9: 9 | E9: 0.85 | F9: =D9*E9 | G9: 85000 | H9: 0.8 | I9: =G9*H9 | J9: 27 | K9: ='Inputs'!$C$11 | L9: =J9/100*K9 | M9: 0.33 | N9: =(L9+M9)*G9 | O9: 46000 | P9: 52000 | Q9: 14000 | R9: =N9+O9+P9+Q9 | S9: =IFERROR(R9/I9,"") | T9: =IFERROR(R9/(I9*F9),"") | U9: Operational class assumption; common distribution/retail class | W9: Editable
A10: Rigid truck 26t | B10: Heavy rigid | C10: 26 | D10: 14 | E10: 0.85 | F10: =D10*E10 | G10: 90000 | H10: 0.82 | I10: =G10*H10 | J10: 31 | K10: ='Inputs'!$C$11 | L10: =J10/100*K10 | M10: 0.4 | N10: =(L10+M10)*G10 | O10: 48000 | P10: 68000 | Q10: 16000 | R10: =N10+O10+P10+Q10 | S10: =IFERROR(R10/I10,"") | T10: =IFERROR(R10/(I10*F10),"") | U10: Operational class assumption; common 3-axle heavy rigid class | W10: Editable
A11: Articulated 40t | B11: Standard heavy artic | C11: 40 | D11: 24 | E11: 0.868 | F11: =D11*E11 | G11: 113100 | H11: 0.853 | I11: =G11*H11 | J11: 34.2 | K11: ='Inputs'!$C$11 | L11: =J11/100*K11 | M11: 0.1716 | N11: =(L11+M11)*G11 | O11: 49674 | P11: 36095 | Q11: 0 | R11: =N11+O11+P11+Q11 | S11: =IFERROR(R11/I11,"") | T11: =IFERROR(R11/(I11*F11),"") | U11: Standard EU heavy-goods reference class; original model anchor | V11: https://ec.europa.eu/commission/presscorner/detail/en/MEMO_13_329 | W11: Editable
A12: Articulated 44t | B12: Intermodal / heavier permitted artic | C12: 44 | D12: 28 | E12: 0.88 | F12: =D12*E12 | G12: 113100 | H12: 0.86 | I12: =G12*H12 | J12: 35.5 | K12: ='Inputs'!$C$11 | L12: =J12/100*K12 | M12: 0.18 | N12: =(L12+M12)*G12 | O12: 50000 | P12: 39000 | Q12: 18000 | R12: =N12+O12+P12+Q12 | S12: =IFERROR(R12/I12,"") | T12: =IFERROR(R12/(I12*F12),"") | U12: 44t only where rules allow, especially combined/intermodal transport | V12: https://ec.europa.eu/commission/presscorner/detail/en/MEMO_13_329 | W12: Editable
A13: EMS / high-capacity 60t | B13: Country/permit dependent EMS | C13: 60 | D13: 38 | E13: 0.9 | F13: =D13*E13 | G13: 115000 | H13: 0.88 | I13: =G13*H13 | J13: 45 | K13: ='Inputs'!$C$11 | L13: =J13/100*K13 | M13: 0.23 | N13: =(L13+M13)*G13 | O13: 53000 | P13: 60000 | Q13: 22000 | R13: =N13+O13+P13+Q13 | S13: =IFERROR(R13/I13,"") | T13: =IFERROR(R13/(I13*F13),"") | U13: Not universal EU-wide; EMS/high-capacity combinations are country/route dependent | V13: https://transport.ec.europa.eu/document/download/45e1073e-373a-4156-966b-0523915dec9f_en?filename=SWD_2023_70_implementation_report_amendments_dir_96_53.pdf | W13: Editable
A15: Note: cost values by truck class are modelling placeholders to make the sensitivity engine work. Replace with actual lease/depreciation, insurance, fuel, toll and driver cost data for commercial decisions.

Sheet Pricing Scenarios
A1: Customer pricing layer after break-even
A3: Markup over break-even | B3: LD rate €/loaded km | C3: LD annual revenue | D3: LD EBIT | E3: LD EBIT margin | F3: Regional rate €/loaded km | G3: Regional annual revenue | H3: Regional EBIT | I3: Regional EBIT margin | K3: Markup | L3: LD final rate | M3: Regional final rate
A4: 0 | B4: =Engine!$C$62*(1+$A4) | C4: =B4*Engine!$C$31 | D4: =C4-Engine!$C$60 | E4: =IFERROR(D4/C4,0) | F4: =Engine!$D$62*(1+$A4) | G4: =F4*Engine!$D$31 | H4: =G4-Engine!$D$60 | I4: =IFERROR(H4/G4,0) | K4: =A4 | L4: =B4 | M4: =F4
A5: 0.05 | B5: =Engine!$C$62*(1+$A5) | C5: =B5*Engine!$C$31 | D5: =C5-Engine!$C$60 | E5: =IFERROR(D5/C5,0) | F5: =Engine!$D$62*(1+$A5) | G5: =F5*Engine!$D$31 | H5: =G5-Engine!$D$60 | I5: =IFERROR(H5/G5,0) | K5: =A5 | L5: =B5 | M5: =F5
A6: 0.1 | B6: =Engine!$C$62*(1+$A6) | C6: =B6*Engine!$C$31 | D6: =C6-Engine!$C$60 | E6: =IFERROR(D6/C6,0) | F6: =Engine!$D$62*(1+$A6) | G6: =F6*Engine!$D$31 | H6: =G6-Engine!$D$60 | I6: =IFERROR(H6/G6,0) | K6: =A6 | L6: =B6 | M6: =F6
A7: 0.125 | B7: =Engine!$C$62*(1+$A7) | C7: =B7*Engine!$C$31 | D7: =C7-Engine!$C$60 | E7: =IFERROR(D7/C7,0) | F7: =Engine!$D$62*(1+$A7) | G7: =F7*Engine!$D$31 | H7: =G7-Engine!$D$60 | I7: =IFERROR(H7/G7,0) | K7: =A7 | L7: =B7 | M7: =F7
A8: 0.15 | B8: =Engine!$C$62*(1+$A8) | C8: =B8*Engine!$C$31 | D8: =C8-Engine!$C$60 | E8: =IFERROR(D8/C8,0) | F8: =Engine!$D$62*(1+$A8) | G8: =F8*Engine!$D$31 | H8: =G8-Engine!$D$60 | I8: =IFERROR(H8/G8,0) | K8: =A8 | L8: =B8 | M8: =F8
A9: 0.2 | B9: =Engine!$C$62*(1+$A9) | C9: =B9*Engine!$C$31 | D9: =C9-Engine!$C$60 | E9: =IFERROR(D9/C9,0) | F9: =Engine!$D$62*(1+$A9) | G9: =F9*Engine!$D$31 | H9: =G9-Engine!$D$60 | I9: =IFERROR(H9/G9,0) | K9: =A9 | L9: =B9 | M9: =F9
A10: 0.25 | B10: =Engine!$C$62*(1+$A10) | C10: =B10*Engine!$C$31 | D10: =C10-Engine!$C$60 | E10: =IFERROR(D10/C10,0) | F10: =Engine!$D$62*(1+$A10) | G10: =F10*Engine!$D$31 | H10: =G10-Engine!$D$60 | I10: =IFERROR(H10/G10,0) | K10: =A10 | L10: =B10 | M10: =F10
A11: 0.3 | B11: =Engine!$C$62*(1+$A11) | C11: =B11*Engine!$C$31 | D11: =C11-Engine!$C$60 | E11: =IFERROR(D11/C11,0) | F11: =Engine!$D$62*(1+$A11) | G11: =F11*Engine!$D$31 | H11: =G11-Engine!$D$60 | I11: =IFERROR(H11/G11,0) | K11: =A11 | L11: =B11 | M11: =F11
A12: 0.35 | B12: =Engine!$C$62*(1+$A12) | C12: =B12*Engine!$C$31 | D12: =C12-Engine!$C$60 | E12: =IFERROR(D12/C12,0) | F12: =Engine!$D$62*(1+$A12) | G12: =F12*Engine!$D$31 | H12: =G12-Engine!$D$60 | I12: =IFERROR(H12/G12,0) | K12: =A12 | L12: =B12 | M12: =F12
A13: 0.4 | B13: =Engine!$C$62*(1+$A13) | C13: =B13*Engine!$C$31 | D13: =C13-Engine!$C$60 | E13: =IFERROR(D13/C13,0) | F13: =Engine!$D$62*(1+$A13) | G13: =F13*Engine!$D$31 | H13: =G13-Engine!$D$60 | I13: =IFERROR(H13/G13,0) | K13: =A13 | L13: =B13 | M13: =F13
A15: Selected pricing assumption | C15: Long Distance 40t | D15: Regional 40t
A16: Selected markup over break-even | B16: % | C16: 0.125 | D16: 0.125
A17: Break-even price | B17: EUR/loaded km | C17: =Engine!$C$62 | D17: =Engine!$D$62
A18: Final customer rate per loaded km | B18: EUR/loaded km | C18: =C17*(1+C16) | D18: =D17*(1+D16)
A19: Annual revenue at final rate | B19: EUR/year | C19: =C18*Engine!$C$31 | D19: =D18*Engine!$D$31
A20: EBIT at final rate | B20: EUR/year | C20: =C19-Engine!$C$60 | D20: =D19-Engine!$D$60
A21: EBIT margin at final rate | B21: % revenue | C21: =IFERROR(C20/C19,0) | D21: =IFERROR(D20/D19,0)
A23: Target margin cross-check | C23: Long Distance 40t | D23: Regional 40t
A24: Target EBIT margin from Inputs | B24: % revenue | C24: =Engine!$C$27 | D24: =Engine!$D$27
A25: Markup needed to reach target margin | B25: % over break-even | C25: =IFERROR(C24/(1-C24),0) | D25: =IFERROR(D24/(1-D24),0)
A26: Rate needed to reach target margin | B26: EUR/loaded km | C26: =Engine!$C$62*(1+C25) | D26: =Engine!$D$62*(1+D25)
A28: Logic note
A29: Break-even is calculated first in Engine row 62.
A30: Customer rate is then calculated here as: break-even price × (1 + markup over break-even).
A31: A 10% markup over break-even is not the same as a 10% EBIT margin; a 10% EBIT margin requires an 11.11% markup over break-even.
A33: Tax-adjusted selected pricing view
A35: Metric | B35: Unit | C35: Long Distance 40t | D35: Regional 40t | E35: Formula / source
A36: Customer rate excl. VAT | B36: EUR/loaded km | C36: ='Company & Tax Profile'!C35 | D36: ='Company & Tax Profile'!D35 | E36: From selected pricing assumption above.
A37: Customer invoice rate incl. VAT | B37: EUR/loaded km | C37: ='Company & Tax Profile'!C36 | D37: ='Company & Tax Profile'!D36 | E37: From Company & Tax Profile.
A38: Annual revenue excl. VAT | B38: EUR/year | C38: ='Company & Tax Profile'!C38 | D38: ='Company & Tax Profile'!D38 | E38: Revenue used for EBIT.
A39: VAT collected / payable | B39: EUR/year | C39: ='Company & Tax Profile'!C39 | D39: ='Company & Tax Profile'!D39 | E39: Cash/invoice layer only, not revenue.
A40: Invoice value incl. VAT | B40: EUR/year | C40: ='Company & Tax Profile'!C40 | D40: ='Company & Tax Profile'!D40 | E40: Customer invoice amount incl. VAT.
A41: EBIT before business tax | B41: EUR/year | C41: ='Company & Tax Profile'!C41 | D41: ='Company & Tax Profile'!D41 | E41: Operational EBIT before company tax.
A42: Business tax charge | B42: EUR/year | C42: ='Company & Tax Profile'!C42 | D42: ='Company & Tax Profile'!D42 | E42: Tax on positive EBIT only.
A43: Profit after business tax | B43: EUR/year | C43: ='Company & Tax Profile'!C43 | D43: ='Company & Tax Profile'!D43 | E43: EBIT minus business tax.
A44: EBIT margin | B44: % revenue | C44: ='Company & Tax Profile'!C44 | D44: ='Company & Tax Profile'!D44 | E44: EBIT / revenue excl. VAT.
A45: After-tax profit margin | B45: % revenue | C45: ='Company & Tax Profile'!C45 | D45: ='Company & Tax Profile'!D45 | E45: Profit after business tax / revenue excl. VAT.
A46: Required rate for target after-tax margin | B46: EUR/loaded km | C46: ='Company & Tax Profile'!C47 | D46: ='Company & Tax Profile'!D47 | E46: From Company & Tax Profile.

Sheet Company & Tax Profile
A1: Company & Tax Profile — Cascading Jurisdiction Logic
A3: Cascade selection | B3: Selected value | C3: Status / formula | D3: Unit | E3: Modelling note
A4: Company country / jurisdiction | B4: Austria | C4: Master field | E4: Drives company type, business model, VAT, corporate tax, payroll contribution and vehicle-tax defaults.
A5: Company type | B5: =XLOOKUP($B$4,'Tax Rules'!$A$2:$A$9,'Tax Rules'!$L$2:$L$9,"") | C5: Depends on country | E5: Dropdown is filtered by selected country/jurisdiction.
A6: Business model | B6: =XLOOKUP($B$4,'Tax Rules'!$A$2:$A$9,'Tax Rules'!$M$2:$M$9,"") | C6: Depends on country + company type | E6: Dropdown is filtered by country and company type.
A7: VAT registered | B7: =XLOOKUP($B$4,'Tax Rules'!$A$2:$A$9,'Tax Rules'!$C$2:$C$9,"Yes") | C7: Pre-filled from country default | D7: Yes/No | E7: VAT does not create profit. It is shown as invoice/cash value only.
A8: Cascade validity | B8: =IF(COUNTIFS('Cascade Lists'!$A:$A,$B$4,'Cascade Lists'!$B:$B,$B$5,'Cascade Lists'!$C:$C,$B$6)>0,"Valid cascade","Reselect company type / business model") | C8: Check | E8: If invalid, reselect company type/business model after changing country.
A9: Standard VAT rate | B9: =XLOOKUP($B$4,'Tax Rules'!$A$2:$A$9,'Tax Rules'!$D$2:$D$9,0) | C9: Pre-filled | D9: % | E9: Standard VAT rate used for customer invoice amount.
A10: Corporate / business income tax rate | B10: =XLOOKUP($B$4,'Tax Rules'!$A$2:$A$9,'Tax Rules'!$E$2:$E$9,0) | C10: Pre-filled | D10: % | E10: Standard corporate rate or simplified business-tax proxy.
A11: Local / trade tax rate | B11: =XLOOKUP($B$4,'Tax Rules'!$A$2:$A$9,'Tax Rules'!$F$2:$F$9,0) | C11: Pre-filled | D11: % | E11: Municipal/local trade tax if applicable. Germany and Hungary are modelled with proxies.
A12: Effective business tax rate | B12: =MIN(MAX($B$10+$B$11,0),1) | C12: Formula | D12: % | E12: Corporate/business tax + local/trade tax, capped between 0% and 100%.
A13: Target after-tax profit margin | B13: =XLOOKUP($B$4,'Tax Rules'!$A$2:$A$9,'Tax Rules'!$K$2:$K$9,0.1) | C13: Pre-filled default | D13: % | E13: Used to calculate required customer rate for target after-tax margin.
A14: Employer payroll contribution rate | B14: =XLOOKUP($B$4,'Tax Rules'!$A$2:$A$9,'Tax Rules'!$H$2:$H$9,0) | C14: Pre-filled | D14: % of gross salary | E14: Used by the Inputs sheet as employer tax rate on salary.
A15: Employee contribution rate | B15: =XLOOKUP($B$4,'Tax Rules'!$A$2:$A$9,'Tax Rules'!$I$2:$I$9,0) | C15: Informational | D15: % of gross salary | E15: Shown for context only; not charged again if salary inputs are gross salary.
A16: Default vehicle tax / truck / year | B16: =XLOOKUP($B$4,'Tax Rules'!$A$2:$A$9,'Tax Rules'!$J$2:$J$9,0) | C16: Pre-filled | D16: EUR/year | E16: Indicative default. Replace with vehicle-specific road/vehicle tax where available.
A17: Currency | B17: =XLOOKUP($B$4,'Tax Rules'!$A$2:$A$9,'Tax Rules'!$B$2:$B$9,"EUR") | C17: Pre-filled | E17: Workbook remains in EUR; non-EUR jurisdictions need FX consistency.
A18: Tax-source as-of | B18: =XLOOKUP($B$4,'Tax Rules'!$A$2:$A$9,'Tax Rules'!$R$2:$R$9,"") | C18: Pre-filled | E18: Date of source-data refresh.
A19: Country rule note | B19: =XLOOKUP($B$4,'Tax Rules'!$A$2:$A$9,'Tax Rules'!$N$2:$N$9,"") | C19: Pre-filled | E19: Country-specific limitations of the simplified model.
A22: Tax values pushed into pricing engine | C22: Long distance 40t | D22: Regional 40t | E22: Source
A23: VAT registered | C23: =$B$7 | D23: =$B$7 | E23: From cascade selection
A24: Standard VAT rate | C24: =$B$9 | D24: =$B$9
A25: Corporate / business income tax rate | C25: =$B$10 | D25: =$B$10 | E25: From cascade selection
A26: Local / trade tax rate | C26: =$B$11 | D26: =$B$11 | E26: From cascade selection
A27: Effective business tax rate | C27: =$B$12 | D27: =$B$12 | E27: Formula: corporate + local/trade tax
A28: Target after-tax profit margin | C28: =$B$13 | D28: =$B$13 | E28: From cascade selection
A29: Number of trucks | C29: 1 | D29: 1 | E29: Manual profile-level assumption
A30: Drivers per truck | C30: =Inputs!C23 | D30: =Inputs!D23 | E30: Linked from Inputs
A31: Total drivers | C31: =C29*C30 | D31: =D29*D30 | E31: Formula
A32: Employer contribution profile | C32: =$B$14 | D32: =$B$14 | E32: From country payroll rule
A33: Vehicle tax annual | C33: =$B$16 | D33: =$B$16 | E33: From country vehicle-tax default
A34: Business tax treatment note | C34: Tax positive EBIT only | D34: Tax positive EBIT only | E34: Model simplification
A35: Selected customer rate excl. VAT | B35: EUR/loaded km | C35: ='Pricing Scenarios'!C18 | D35: ='Pricing Scenarios'!D18 | E35: From Pricing Scenarios selected markup
A36: Customer invoice rate incl. VAT | B36: EUR/loaded km | C36: =IF(C23="Yes",C35*(1+C24),C35) | D36: =IF(D23="Yes",D35*(1+D24),D35) | E36: Formula: excl. VAT × (1 + VAT) if VAT registered
A37: Loaded km / year | B37: km/year | C37: =Engine!C31 | D37: =Engine!D31 | E37: From Engine
A38: Annual revenue excl. VAT | B38: EUR/year | C38: =C35*C37 | D38: =D35*D37 | E38: Customer rate excl. VAT × loaded km/year
A39: VAT collected / payable | B39: EUR/year | C39: =IF(C23="Yes",C38*C24,0) | D39: =IF(D23="Yes",D38*D24,0) | E39: Invoice VAT component
A40: Invoice value incl. VAT | B40: EUR/year | C40: =C38+C39 | D40: =D38+D39 | E40: Revenue excl. VAT + VAT
A41: EBIT before business tax | B41: EUR/year | C41: =C38-Engine!C60 | D41: =D38-Engine!D60 | E41: Revenue excl. VAT - operating total cost
A42: Business tax charge | C42: =MAX(0,C41)*C27 | D42: =MAX(0,D41)*D27
A43: Profit after business tax | B43: EUR/year | C43: =C41-C42 | D43: =D41-D42 | E43: EBIT - business tax
...

Sheet Tax Rules
A1: Country / jurisdiction | B1: Currency | C1: Default VAT registered | D1: Standard VAT rate | E1: Corporate / business income tax rate | F1: Local / trade business tax rate | G1: Effective business tax rate | H1: Employer payroll contribution rate | I1: Employee contribution rate | J1: Default vehicle tax / truck / year | K1: Default target after-tax margin | L1: Default company type | M1: Default business model | N1: Modelling note | O1: VAT source URL | P1: Corporate tax source URL | Q1: Payroll source URL | R1: As-of
A2: Austria | B2: EUR | C2: Yes | D2: 0.2 | E2: 0.23 | F2: 0 | G2: 0.23 | H2: 0.2098 | I2: 0.1807 | J2: 800 | K2: 0.1 | L2: GmbH | M2: Fleet operator | N2: Corporate rate used for GmbH/AG. Sole traders are subject to progressive personal income tax; validate separately. Vehicle tax is indicative and should be replaced with vehicle-specific Austrian motor/tax data. | O2: https://www.usp.gv.at/en/themen/steuern-finanzen/umsatzsteuer-ueberblick/steuersaetze-und-steuerbefreiungen-der-umsatzsteuer.html | P2: https://www.usp.gv.at/en/themen/steuern-finanzen/koerperschaftsteuer-ueberblick.html | Q2: https://taxsummaries.pwc.com/austria/individual/other-taxes | R2: 2026-05
A3: Germany | B3: EUR | C3: Yes | D3: 0.19 | E3: 0.15825 | F3: 0.14 | G3: 0.29825 | H3: 0.1942 | I3: 0.1933 | J3: 900 | K3: 0.1 | L3: GmbH | M3: Fleet operator | N3: Corporate tax includes 15% Körperschaftsteuer plus 5.5% solidarity surcharge on CIT. Trade tax is municipal; 14% is an average modelling proxy and should be replaced with the exact municipality rate. | O3: https://taxation-customs.ec.europa.eu/taxation/vat/vat-directive/vat-rates_en | P3: https://taxsummaries.pwc.com/germany/corporate/taxes-on-corporate-income | Q3: https://taxsummaries.pwc.com/germany/individual/other-taxes | R3: 2026-05
A4: Romania | B4: RON/EUR | C4: Yes | D4: 0.21 | E4: 0.16 | F4: 0 | G4: 0.16 | H4: 0.0225 | I4: 0.35 | J4: 500 | K4: 0.1 | L4: SRL | M4: Fleet operator | N4: Standard CIT used for SRL/SA. Micro-company turnover tax regimes and special working-condition contributions are not modelled by default. VAT standard rate increased to 21% from 1 August 2025. | O4: https://www.ey.com/en_gl/technical/tax-alerts/romanian-tax-changes-introduced-by-new-fiscal-and-budgetary-measures | P4: https://www.accace.com/tax-guideline-for-romania/ | Q4: https://taxsummaries.pwc.com/romania/individual/other-taxes | R4: 2026-05
A5: Hungary | B5: HUF/EUR | C5: Yes | D5: 0.27 | E5: 0.09 | F5: 0.02 | G5: 0.11 | H5: 0.13 | I5: 0.185 | J5: 500 | K5: 0.1 | L5: Kft. | M5: Fleet operator | N5: Local business tax can be up to 2% and is not an EBIT tax; the model uses it as a simplified profit-tax proxy for pricing sensitivity. Validate with municipality and accountant. | O5: https://taxation-customs.ec.europa.eu/taxation/vat/vat-directive/vat-rates_en | P5: https://taxsummaries.pwc.com/hungary/corporate/taxes-on-corporate-income | Q5: https://taxsummaries.pwc.com/hungary/individual/other-taxes | R5: 2026-05
A6: Bulgaria | B6: BGN/EUR | C6: Yes | D6: 0.2 | E6: 0.1 | F6: 0 | G6: 0.1 | H6: 0.193 | I6: 0.1378 | J6: 400 | K6: 0.1 | L6: EOOD/OOD | M6: Fleet operator | N6: Flat 10% CIT used. Employer contribution uses mid-point of published 2026 range; actual rate depends on activity class and caps. No provincial/local corporate income tax. | O6: https://taxsummaries.pwc.com/bulgaria/corporate/other-taxes | P6: https://taxsummaries.pwc.com/bulgaria/corporate/taxes-on-corporate-income | Q6: https://taxsummaries.pwc.com/bulgaria/individual/other-taxes | R6: 2026-05
A7: Czechia | B7: CZK/EUR | C7: Yes | D7: 0.21 | E7: 0.21 | F7: 0 | G7: 0.21 | H7: 0.338 | I7: 0.116 | J7: 550 | K7: 0.1 | L7: s.r.o. | M7: Fleet operator | N7: Standard corporate rate used for s.r.o./a.s. Employer contribution combines 24.8% social security and 9% health insurance. Vehicle tax is indicative. | O7: https://taxation-customs.ec.europa.eu/taxation/vat/vat-directive/vat-rates_en | P7: https://portal.gov.cz/en/informace/what-is-the-corporate-income-tax-rate-INF-329 | Q7: https://taxsummaries.pwc.com/czech-republic/individual/other-taxes | R7: 2026-05
A8: Slovakia | B8: EUR | C8: Yes | D8: 0.23 | E8: 0.21 | F8: 0 | G8: 0.21 | H8: 0.362 | I8: 0.144 | J8: 550 | K8: 0.1 | L8: s.r.o. | M8: Fleet operator | N8: Default CIT rate assumes taxable income above EUR 100k and up to EUR 5m. 10% micro and 24% high-income bands may apply. Employer contributions total 36.2% in 2026. | O8: https://taxsummaries.pwc.com/slovak-republic/corporate/other-taxes | P8: https://www.accace.com/tax-guideline-for-slovakia/ | Q8: https://taxsummaries.pwc.com/slovak-republic/corporate/other-taxes | R8: 2026-05
A9: Manual / Custom | B9: EUR | C9: No | D9: 0 | E9: 0 | F9: 0 | G9: 0 | H9: 0 | I9: 0 | J9: 0 | K9: 0.1 | L9: Manual entity | M9: Fleet operator | N9: Use this option when the jurisdiction or exact legal entity is not included. Replace all default rates manually before using the model commercially. | O9: Manual input | P9: Manual input | Q9: Manual input | R9: 2026-05

Sheet Cascade Lists
A1: Country / jurisdiction | B1: Company type | C1: Business model | D1: Status
A2: Austria | B2: Einzelunternehmen | C2: Owner-operator | D2: Available
A3: Austria | B3: Einzelunternehmen | C3: Fleet operator | D3: Available
A4: Austria | B4: Einzelunternehmen | C4: Subcontractor | D4: Available
A5: Austria | B5: Einzelunternehmen | C5: Mixed | D5: Available
A6: Austria | B6: Einzelunternehmen | C6: Carrier with subcontractors | D6: Available
A7: Austria | B7: GmbH | C7: Owner-operator | D7: Available
A8: Austria | B8: GmbH | C8: Fleet operator | D8: Available
A9: Austria | B9: GmbH | C9: Subcontractor | D9: Available
A10: Austria | B10: GmbH | C10: Mixed | D10: Available
A11: Austria | B11: GmbH | C11: Carrier with subcontractors | D11: Available
A12: Austria | B12: AG | C12: Owner-operator | D12: Available
... A151: Manual / Custom | B151: Manual entity | C151: Carrier with subcontractors | D151: Available

Sheet Dropdown Helper
A1: Company types for selected country | C1: Business models for selected country + company type | E1: Yes/No list
A2: {=UNIQUE(_xlfn._xlws.FILTER('Cascade Lists'!$B$2:$B$300,'Cascade Lists'!$A$2:$A$300='Company & Tax Profile'!$B$3,""))} | C2: {=UNIQUE(_xlfn._xlws.FILTER('Cascade Lists'!$C$2:$C$300,('Cascade Lists'!$A$2:$A$300='Company & Tax Profile'!$B$3)*('Cascade Lists'!$B$2:$B$300='Company & Tax Profile'!$B$4),""))} | E2: Yes
E3: No
