Workbook

Sheet Start Here
A1: Transport Break-Even Engine — Start Here
A2: Purpose | B2: Use this workbook in the order below: select jurisdiction, fill operational inputs, review break-even, then price with markup and tax view.
A4: Step | B4: Sheet | C4: What you do | D4: Editable? | E4: Result
A5: 1 | B5: Company & Tax Profile | C5: Select country/jurisdiction, company type, and business model. | D5: Yes | E5: Tax defaults and company profile are prefilled.
A6: 2 | B6: Inputs | C6: Fill daily km, operating days, loaded ratio, costs, driver assumptions and overhead. | D6: Yes | E6: Annual km and operating costs are calculated.
A7: 3 | B7: Engine | C7: Read operational break-even and total annual cost. | D7: No | E7: Break-even €/loaded km and €/tonne-km.
A8: 4 | B8: Pricing Scenarios | C8: Choose markup over break-even. | D8: Yes | E8: Customer rate, VAT invoice rate, EBIT and after-tax margin.
A9: 5 | B9: Sensitivity | C9: Review utilisation, rate, payload and vehicle-class sensitivity. | D9: Mostly no | E9: Shows risk from low load factor and wrong truck class.
A10: 6 | B10: Vehicle Classes / Tax Rules | C10: Update defaults only when you have better fleet or tax data. | D10: Advanced | E10: Better assumptions for future scenarios.
A12: Current model summary
A13: Profile | B13: Country | C13: Annual km | D13: Loaded km | E13: Break-even €/loaded km | F13: Selected rate excl. VAT | G13: Invoice rate incl. VAT | H13: After-tax margin
A14: Long Distance 40t | B14: ='Company & Tax Profile'!$B$4 -> Bulgaria | C14: =Engine!$C$3 -> 113100 | D14: =Engine!$C$31 -> 96474.3 | E14: =Engine!$C$62 -> 1.5328577 | F14: ='Pricing Scenarios'!$C$18 -> 1.7244649 | G14: ='Company & Tax Profile'!$C$36 -> 2.0693579 | H14: ='Pricing Scenarios'!$C$45 -> 0.093333333
A15: Regional 40t | B15: ='Company & Tax Profile'!$B$4 -> Bulgaria | C15: =Engine!$D$3 -> 98000 | D15: =Engine!$D$31 -> 78890 | E15: =Engine!$D$62 -> 1.6676528 | F15: ='Pricing Scenarios'!$D$18 -> 1.8761094 | G15: ='Company & Tax Profile'!$D$36 -> 2.2513313 | H15: ='Pricing Scenarios'!$D$45 -> 0.093333333
A17: Colour legend
A18: Yellow | B18: Editable input
A19: Light blue | B19: Formula / linked value
A20: Light green | B20: Key output
A21: Grey | B21: Instruction / modelling note
A23: Important modelling rule | B23: VAT is not profit. It is shown only as invoice/cash value. Business profitability uses customer rate excluding VAT.
A24: Important modelling rule | B24: Customer rate is not an input in Inputs. It is calculated after break-even in Pricing Scenarios.

Sheet Company & Tax Profile
A1: Company & Tax Profile — Cascading Jurisdiction Logic
A3: Cascade selection | B3: Selected value | C3: Status / formula | D3: Unit | E3: Modelling note
A4: Company country / jurisdiction | B4: Bulgaria | C4: Master field | E4: Drives company type, business model, VAT, corporate tax, payroll contribution and vehicle-tax defaults.
A5: Company type | B5: =IFERROR(INDEX('Tax Rules'!$L$2:$L$9,MATCH($B$4,'Tax Rules'!$A$2:$A$9,0)),"") -> EOOD/OOD | C5: Depends on country | E5: Dropdown is controlled by country/jurisdiction. Formula uses INDEX/MATCH for Excel compatibility.
A6: Business model | B6: =IFERROR(INDEX('Tax Rules'!$M$2:$M$9,MATCH($B$4,'Tax Rules'!$A$2:$A$9,0)),"") -> Fleet operator | C6: Depends on country + company type | E6: Dropdown uses approved operating models. Cascade validity checks country + company type + business model.
A7: VAT registered | B7: =IFERROR(INDEX('Tax Rules'!$C$2:$C$9,MATCH($B$4,'Tax Rules'!$A$2:$A$9,0)),"Yes") -> Yes | C7: Pre-filled from country default | D7: Yes/No | E7: VAT does not create profit. It is shown as invoice/cash value only.
A8: Cascade validity | B8: =IF(AND($B$4<>"",$B$5<>"",$B$6<>"",COUNTIFS('Cascade Lists'!$A:$A,$B$4,'Cascade Lists'!$B:$B,$B$5,'Cascade Lists'!$C:$C,$B$6)>0),"Valid cascade","Reselect company type / business model") -> Valid cascade | C8: Check | E8: If invalid, reselect company type/business model after changing country.
A9: Standard VAT rate | B9: =IFERROR(INDEX('Tax Rules'!$D$2:$D$9,MATCH($B$4,'Tax Rules'!$A$2:$A$9,0)),0) -> 0.2 | C9: Pre-filled | D9: % | E9: Standard VAT rate used for customer invoice amount.
A10: Corporate / business income tax rate | B10: =IFERROR(INDEX('Tax Rules'!$E$2:$E$9,MATCH($B$4,'Tax Rules'!$A$2:$A$9,0)),0) -> 0.1 | C10: Pre-filled | D10: % | E10: Standard corporate rate or simplified business-tax proxy.
A11: Local / trade tax rate | B11: =IFERROR(INDEX('Tax Rules'!$F$2:$F$9,MATCH($B$4,'Tax Rules'!$A$2:$A$9,0)),0) -> 0 | C11: Pre-filled | D11: % | E11: Municipal/local trade tax if applicable. Germany and Hungary are modelled with proxies.
A12: Effective business tax rate | B12: =MIN(MAX($B$10+$B$11,0),1) -> 0.1 | C12: Formula | D12: % | E12: Corporate/business tax + local/trade tax, capped between 0% and 100%.
A13: Target after-tax profit margin | B13: =IFERROR(INDEX('Tax Rules'!$K$2:$K$9,MATCH($B$4,'Tax Rules'!$A$2:$A$9,0)),0.1) -> 0.1 | C13: Pre-filled default | D13: % | E13: Used to calculate required customer rate for target after-tax margin.
A14: Employer payroll contribution rate | B14: =IFERROR(INDEX('Tax Rules'!$H$2:$H$9,MATCH($B$4,'Tax Rules'!$A$2:$A$9,0)),0) -> 0.193 | C14: Pre-filled | D14: % of gross salary | E14: Used by the Inputs sheet as employer tax rate on salary.
A15: Employee contribution rate | B15: =IFERROR(INDEX('Tax Rules'!$I$2:$I$9,MATCH($B$4,'Tax Rules'!$A$2:$A$9,0)),0) -> 0.1378 | C15: Informational | D15: % of gross salary | E15: Shown for context only; not charged again if salary inputs are gross salary.
A16: Default vehicle tax / truck / year | B16: =IFERROR(INDEX('Tax Rules'!$J$2:$J$9,MATCH($B$4,'Tax Rules'!$A$2:$A$9,0)),0) -> 400 | C16: Pre-filled | D16: EUR/year | E16: Indicative default. Replace with vehicle-specific road/vehicle tax where available.
A17: Currency | B17: =IFERROR(INDEX('Tax Rules'!$B$2:$B$9,MATCH($B$4,'Tax Rules'!$A$2:$A$9,0)),"EUR") -> BGN/EUR | C17: Pre-filled | E17: Workbook remains in EUR; non-EUR jurisdictions need FX consistency.
A18: Tax-source as-of | B18: =IFERROR(INDEX('Tax Rules'!$R$2:$R$9,MATCH($B$4,'Tax Rules'!$A$2:$A$9,0)),"") -> 2026-05 | C18: Pre-filled | E18: Date of source-data refresh.
A19: Country rule note | B19: =IFERROR(INDEX('Tax Rules'!$N$2:$N$9,MATCH($B$4,'Tax Rules'!$A$2:$A$9,0)),"") -> Flat 10% CIT used. Employer contribution uses mid-point of published 2026 range; actual rate depends on activity class and caps. No provincial/local corporate income tax. | C19: Pre-filled | E19: Country-specific limitations of the simplified model.
A22: Tax values pushed into pricing engine | C22: Long distance 40t | D22: Regional 40t | E22: Source
A23: VAT registered | C23: =$B$7 -> Yes | D23: =$B$7 -> Yes | E23: From cascade selection
A24: Standard VAT rate | C24: =$B$9 -> 0.2 | D24: =$B$9 -> 0.2
A25: Corporate / business income tax rate | C25: =$B$10 -> 0.1 | D25: =$B$10 -> 0.1 | E25: From cascade selection
A26: Local / trade tax rate | C26: =$B$11 -> 0 | D26: =$B$11 -> 0 | E26: From cascade selection
A27: Effective business tax rate | C27: =$B$12 -> 0.1 | D27: =$B$12 -> 0.1 | E27: Formula: corporate + local/trade tax
A28: Target after-tax profit margin | C28: =$B$13 -> 0.1 | D28: =$B$13 -> 0.1 | E28: From cascade selection
A29: Number of trucks | C29: 1 | D29: 1 | E29: Manual profile-level assumption
A30: Drivers per truck | C30: =Inputs!C23 -> 1.064 | D30: =Inputs!D23 -> 1.085 | E30: Linked from Inputs
A31: Total drivers | C31: =C29*C30 -> 1.064 | D31: =D29*D30 -> 1.085 | E31: Formula
A32: Employer contribution profile | C32: =$B$14 -> 0.193 | D32: =$B$14 -> 0.193 | E32: From country payroll rule
A33: Vehicle tax annual | C33: =$B$16 -> 400 | D33: =$B$16 -> 400 | E33: From country vehicle-tax default
A34: Business tax treatment note | C34: Tax positive EBIT only | D34: Tax positive EBIT only | E34: Model simplification
A35: Selected customer rate excl. VAT | B35: EUR/loaded km | C35: ='Pricing Scenarios'!C18 -> 1.7244649 | D35: ='Pricing Scenarios'!D18 -> 1.8761094 | E35: From Pricing Scenarios selected markup
A36: Customer invoice rate incl. VAT | B36: EUR/loaded km | C36: =IF(C23="Yes",C35*(1+C24),C35) -> 2.0693579 | D36: =IF(D23="Yes",D35*(1+D24),D35) -> 2.2513313 | E36: Formula: excl. VAT × (1 + VAT) if VAT registered
A37: Loaded km / year | B37: km/year | C37: =Engine!C31 -> 96474.3 | D37: =Engine!D31 -> 78890 | E37: From Engine
A38: Annual revenue excl. VAT | B38: EUR/year | C38: =C35*C37 -> 166366.54 | D38: =D35*D37 -> 148006.27 | E38: Customer rate excl. VAT × loaded km/year
A39: VAT collected / payable | B39: EUR/year | C39: =IF(C23="Yes",C38*C24,0) -> 33273.309 | D39: =IF(D23="Yes",D38*D24,0) -> 29601.254 | E39: Invoice VAT component
A40: Invoice value incl. VAT | B40: EUR/year | C40: =C38+C39 -> 199639.85 | D40: =D38+D39 -> 177607.53 | E40: Revenue excl. VAT + VAT
A41: EBIT before business tax | B41: EUR/year | C41: =C38-Engine!C60 -> 18485.171 | D41: =D38-Engine!D60 -> 16445.141 | E41: Revenue excl. VAT - operating total cost
A42: Business tax charge | C42: =MAX(0,C41)*C27 -> 1848.5171 | D42: =MAX(0,D41)*D27 -> 1644.5141
A43: Profit after business tax | B43: EUR/year | C43: =C41-C42 -> 16636.654 | D43: =D41-D42 -> 14800.627 | E43: EBIT - business tax
...

Sheet Inputs
A1: Input | B1: Unit | C1: Long Distance 40t | D1: Regional 40t | E1: Comment
A2: Daily km | B2: km/day | C2: 495.18389 | D2: 421.50538 | E2: Editable daily distance; annual total km is calculated as daily km × operating days
A3: Operating days | B3: days/year | C3: 228.4 | D3: 232.5 | E3: Vehicle operating days
A4: Working days | B4: days/year | C4: 215.2 | D4: 214.6 | E4: Used for driver allowance calculation
A5: Annual working hours | B5: hours/year | C5: 2123 | D5: 2058 | E5: Available driver working hours
A6: Average speed | B6: km/h | C6: 63.9 | D6: 62.5 | E6: Used to estimate driving hours
A7: Loaded ratio | B7: % loaded km | C7: 0.853 | D7: 0.805 | E7: Revenue km divided by total km
A8: Capacity utilisation | B8: % capacity | C8: 0.868 | D8: 0.939 | E8: Payload/capacity usage; diagnostic only
A9: Waiting/loading/unloading time | B9: hours/day | C9: 3.3833333 | D9: 3.4 | E9: Converted from original waiting-time text
A10: Fuel consumption | B10: L/100km | C10: 34.2 | D10: 33.8 | E10: Average consumption
A11: Fuel price excl. VAT | B11: EUR/L | C11: 1.2655246 | D11: 1.2655246 | E11: Original formula 5.91 / 4.67
A12: Tyres annual cost | B12: EUR/year | C12: 3098 | D12: 3101
A13: Maintenance annual cost | B13: EUR/year | C13: 8221 | D13: 7278
A14: Road fees annual cost | B14: EUR/year | C14: 8090 | D14: 5805
A15: Tractor ownership annual cost | B15: EUR/year | C15: 10793 | D15: 10934
A16: Trailer ownership annual cost | B16: EUR/year | C16: 3208 | D16: 3551
A17: Vehicle insurance annual | B17: EUR/year | C17: 2198 | D17: 2598
A18: Cargo insurance annual | B18: EUR/year | C18: 477 | D18: 411
A19: Vehicle taxes annual | B19: EUR/year | C19: ='Company & Tax Profile'!$B$16 -> 400 | D19: ='Company & Tax Profile'!$B$16 -> 400 | E19: Linked from Company & Tax Profile; replace country default with vehicle-specific tax if needed.
A20: Monthly driver salary | B20: EUR/month | C20: 2348.72 | D20: 2182.15
A21: Employer tax rate on salary | B21: % | C21: ='Company & Tax Profile'!$B$14 -> 0.193 | D21: ='Company & Tax Profile'!$B$14 -> 0.193 | E21: Linked from Company & Tax Profile employer payroll contribution rate.
A22: Travel allowance per working day | B22: EUR/day | C22: 38.36 | D22: 16.53
A23: Drivers per vehicle | B23: count | C23: 1.064 | D23: 1.085
A24: Structural overhead annual | B24: EUR/year | C24: 17886 | D24: 17820
A25: Commercial/admin overhead annual cost | B25: EUR/year | C25: 0 | D25: 0 | E25: Optional general commercial overhead, set to zero by default
A26: Target EBIT margin | B26: % revenue | C26: 0.1 | D26: 0.1 | E26: Required margin on revenue
A27: Customer pricing source | B27: sheet | C27: Pricing Scenarios | D27: Pricing Scenarios | E27: Customer rate is calculated after break-even; it is no longer an input assumption.
A28: Computed annual total km | B28: km/year | C28: =C2*C3 -> 113100 | D28: =D2*D3 -> 98000 | E28: Formula: daily km × operating days

Sheet Engine
A1: Metric | B1: Unit | C1: Long Distance 40t | D1: Regional 40t | E1: Formula logic
A2: Input links
A3: Annual total km | B3: km/year | C3: =Inputs!C28 -> 113100 | D3: =Inputs!D28 -> 98000 | E3: Computed from daily km × operating days
A4: Operating days | B4: days/year | C4: =Inputs!C3 -> 228.4 | D4: =Inputs!D3 -> 232.5 | E4: Inputs
A5: Working days | B5: days/year | C5: =Inputs!C4 -> 215.2 | D5: =Inputs!D4 -> 214.6 | E5: Inputs
A6: Annual working hours | B6: hours/year | C6: =Inputs!C5 -> 2123 | D6: =Inputs!D5 -> 2058 | E6: Inputs
A7: Average speed | B7: km/h | C7: =Inputs!C6 -> 63.9 | D7: =Inputs!D6 -> 62.5 | E7: Inputs
A8: Loaded ratio | B8: % loaded km | C8: =Inputs!C7 -> 0.853 | D8: =Inputs!D7 -> 0.805 | E8: Inputs
A9: Capacity utilisation | B9: % capacity | C9: =Inputs!C8 -> 0.868 | D9: =Inputs!D8 -> 0.939 | E9: Diagnostic
A10: Waiting/loading/unloading time | B10: hours/day | C10: =Inputs!C9 -> 3.3833333 | D10: =Inputs!D9 -> 3.4 | E10: Inputs
A11: Fuel consumption | B11: L/100km | C11: =Inputs!C10 -> 34.2 | D11: =Inputs!D10 -> 33.8 | E11: Inputs
A12: Fuel price excl. VAT | B12: EUR/L | C12: =Inputs!C11 -> 1.2655246 | D12: =Inputs!D11 -> 1.2655246 | E12: Inputs
A13: Tyres annual cost | B13: EUR/year | C13: =Inputs!C12 -> 3098 | D13: =Inputs!D12 -> 3101 | E13: Inputs
A14: Maintenance annual cost | B14: EUR/year | C14: =Inputs!C13 -> 8221 | D14: =Inputs!D13 -> 7278 | E14: Inputs
A15: Road fees annual cost | B15: EUR/year | C15: =Inputs!C14 -> 8090 | D15: =Inputs!D14 -> 5805 | E15: Inputs
... A27: Target EBIT margin | B27: % revenue | C27: =Inputs!C26 -> 0.1 | D27: =Inputs!D26 -> 0.1 | E27: Inputs
A28: Selected customer rate per loaded km | B28: EUR/loaded km | C28: ='Pricing Scenarios'!C18 -> 1.7244649 | D28: ='Pricing Scenarios'!D18 -> 1.8761094 | E28: Calculated in Pricing Scenarios after break-even price
A30: Operational outputs
A31: Loaded revenue km | B31: km/year | C31: =IFERROR(C3*C8,0) -> 96474.3 | D31: =IFERROR(D3*D8,0) -> 78890 | E31: Annual total km × loaded ratio
A32: Empty/non-revenue km | B32: km/year | C32: =IFERROR(C3-C31,0) -> 16625.7 | D32: =IFERROR(D3-D31,0) -> 19110 | E32: Annual total km - loaded km
A33: Driving hours | B33: hours/year | C33: =IFERROR(C3/C7,0) -> 1769.9531 | D33: =IFERROR(D3/D7,0) -> 1568 | E33: Annual total km / average speed
A34: Waiting/loading/unloading hours | B34: hours/year | C34: =IFERROR(C4*C10,0) -> 772.75333 | D34: =IFERROR(D4*D10,0) -> 790.5 | E34: Operating days × waiting time/day
A35: Total activity hours | B35: hours/year | C35: =IFERROR(C33+C34,0) -> 2542.7064 | D35: =IFERROR(D33+D34,0) -> 2358.5 | E35: Driving hours + waiting/loading/unloading hours
A37: Variable cost block
A38: Fuel cost | B38: EUR/total km | C38: =IFERROR(C11/100*C12,0) -> 0.43280942 | D38: =IFERROR(D11/100*D12,0) -> 0.42774732 | E38: Fuel consumption / 100 × fuel price
A39: Tyres cost | B39: EUR/total km | C39: =IFERROR(C13/C3,0) -> 0.027391689 | D39: =IFERROR(D13/D3,0) -> 0.031642857 | E39: Annual tyres / annual total km
A40: Maintenance cost | B40: EUR/total km | C40: =IFERROR(C14/C3,0) -> 0.072687887 | D40: =IFERROR(D14/D3,0) -> 0.074265306 | E40: Annual maintenance / annual total km
A41: Road fees cost | B41: EUR/total km | C41: =IFERROR(C15/C3,0) -> 0.07152962 | D41: =IFERROR(D15/D3,0) -> 0.059234694 | E41: Annual road fees / annual total km
A42: Variable operating cost | B42: EUR/total km | C42: =SUM(C38:C41) -> 0.60441862 | D42: =SUM(D38:D41) -> 0.59289018 | E42: Fuel + tyres + maintenance + road fees
A43: Variable operating cost | B43: EUR/loaded km | C43: =IFERROR(C42/C8,0) -> 0.70857986 | D43: =IFERROR(D42/D8,0) -> 0.73650954 | E43: Variable cost per total km / loaded ratio
A44: Annual variable operating cost | B44: EUR/year | C44: =IFERROR(C42*C3,0) -> 68359.746 | D44: =IFERROR(D42*D3,0) -> 58103.238 | E44: Variable cost per total km × annual total km
A46: Driver cost block
A47: Salary incl. employer taxes | B47: EUR/year | C47: =IFERROR(C21*12*C24*(1+C22),0) -> 35776.229 | D47: =IFERROR(D21*12*D24*(1+D22),0) -> 33895.03 | E47: Monthly salary × 12 × drivers × (1 + tax rate)
A48: Travel allowance | B48: EUR/year | C48: =IFERROR(C23*C5*C24,0) -> 8783.3966 | D48: =IFERROR(D23*D5*D24,0) -> 3848.8617 | E48: Allowance/day × working days × drivers
A49: Total driver cost | B49: EUR/year | C49: =SUM(C47:C48) -> 44559.626 | D49: =SUM(D47:D48) -> 37743.892 | E49: Salary incl. taxes + allowance
A50: Driver cost per activity hour | B50: EUR/hour | C50: =IFERROR(C49/C35,0) -> 17.524487 | D50: =IFERROR(D49/D35,0) -> 16.003346 | E50: Total driver cost / activity hours
A51: Driver cost per loaded km | B51: EUR/loaded km | C51: =IFERROR(C49/C31,0) -> 0.46188079 | D51: =IFERROR(D49/D31,0) -> 0.47843697 | E51: Total driver cost / loaded km
A53: Fixed cost block
A54: Vehicle fixed cost | B54: EUR/year | C54: =SUM(C16:C20) -> 17076 | D54: =SUM(D16:D20) -> 17894 | E54: Tractor + trailer + insurance + taxes
A55: Structural/admin fixed cost | B55: EUR/year | C55: =SUM(C25:C26) -> 17886 | D55: =SUM(D25:D26) -> 17820 | E55: Structural overhead + commercial/admin overhead
...

Sheet Pricing Scenarios
A1: Customer pricing layer after break-even
A3: Markup over break-even | B3: LD rate €/loaded km | C3: LD annual revenue | D3: LD EBIT | E3: LD EBIT margin | F3: Regional rate €/loaded km | G3: Regional annual revenue | H3: Regional EBIT | I3: Regional EBIT margin | K3: Markup | L3: LD final rate | M3: Regional final rate
A4: 0 | B4: =Engine!$C$62*(1+$A4) -> 1.5328577 | C4: =B4*Engine!$C$31 -> 147881.37 | D4: =C4-Engine!$C$60 -> 0 | E4: =IFERROR(D4/C4,0) -> 0 | F4: =Engine!$D$62*(1+$A4) -> 1.6676528 | G4: =F4*Engine!$D$31 -> 131561.13 | H4: =G4-Engine!$D$60 -> 0 | I4: =IFERROR(H4/G4,0) -> 0 | K4: =A4 -> 0 | L4: =B4 -> 1.5328577 | M4: =F4 -> 1.6676528
A5: 0.05 | B5: =Engine!$C$62*(1+$A5) -> 1.6095006 | C5: =B5*Engine!$C$31 -> 155275.44 | D5: =C5-Engine!$C$60 -> 7394.0686 | E5: =IFERROR(D5/C5,0) -> 0.047619048 | F5: =Engine!$D$62*(1+$A5) -> 1.7510354 | G5: =F5*Engine!$D$31 -> 138139.19 | H5: =G5-Engine!$D$60 -> 6578.0565 | I5: =IFERROR(H5/G5,0) -> 0.047619048 | K5: =A5 -> 0.05 | L5: =B5 -> 1.6095006 | M5: =F5 -> 1.7510354
A6: 0.1 | B6: =Engine!$C$62*(1+$A6) -> 1.6861434 | C6: =B6*Engine!$C$31 -> 162669.51 | D6: =C6-Engine!$C$60 -> 14788.137 | E6: =IFERROR(D6/C6,0) -> 0.090909091 | F6: =Engine!$D$62*(1+$A6) -> 1.8344181 | G6: =F6*Engine!$D$31 -> 144717.24 | H6: =G6-Engine!$D$60 -> 13156.113 | I6: =IFERROR(H6/G6,0) -> 0.090909091 | K6: =A6 -> 0.1 | L6: =B6 -> 1.6861434 | M6: =F6 -> 1.8344181
A7: 0.125 | B7: =Engine!$C$62*(1+$A7) -> 1.7244649 | C7: =B7*Engine!$C$31 -> 166366.54 | D7: =C7-Engine!$C$60 -> 18485.171 | E7: =IFERROR(D7/C7,0) -> 0.11111111 | F7: =Engine!$D$62*(1+$A7) -> 1.8761094 | G7: =F7*Engine!$D$31 -> 148006.27 | H7: =G7-Engine!$D$60 -> 16445.141 | I7: =IFERROR(H7/G7,0) -> 0.11111111 | K7: =A7 -> 0.125 | L7: =B7 -> 1.7244649 | M7: =F7 -> 1.8761094
A8: 0.15 | B8: =Engine!$C$62*(1+$A8) -> 1.7627863 | C8: =B8*Engine!$C$31 -> 170063.58 | D8: =C8-Engine!$C$60 -> 22182.206 | E8: =IFERROR(D8/C8,0) -> 0.13043478 | F8: =Engine!$D$62*(1+$A8) -> 1.9178007 | G8: =F8*Engine!$D$31 -> 151295.3 | H8: =G8-Engine!$D$60 -> 19734.169 | I8: =IFERROR(H8/G8,0) -> 0.13043478 | K8: =A8 -> 0.15 | L8: =B8 -> 1.7627863 | M8: =F8 -> 1.9178007
A9: 0.2 | B9: =Engine!$C$62*(1+$A9) -> 1.8394292 | C9: =B9*Engine!$C$31 -> 177457.65 | D9: =C9-Engine!$C$60 -> 29576.274 | E9: =IFERROR(D9/C9,0) -> 0.16666667 | F9: =Engine!$D$62*(1+$A9) -> 2.0011834 | G9: =F9*Engine!$D$31 -> 157873.36 | H9: =G9-Engine!$D$60 -> 26312.226 | I9: =IFERROR(H9/G9,0) -> 0.16666667 | K9: =A9 -> 0.2 | L9: =B9 -> 1.8394292 | M9: =F9 -> 2.0011834
A10: 0.25 | B10: =Engine!$C$62*(1+$A10) -> 1.9160721 | C10: =B10*Engine!$C$31 -> 184851.71 | D10: =C10-Engine!$C$60 -> 36970.343 | E10: =IFERROR(D10/C10,0) -> 0.2 | F10: =Engine!$D$62*(1+$A10) -> 2.084566 | G10: =F10*Engine!$D$31 -> 164451.41 | H10: =G10-Engine!$D$60 -> 32890.282 | I10: =IFERROR(H10/G10,0) -> 0.2 | K10: =A10 -> 0.25 | L10: =B10 -> 1.9160721 | M10: =F10 -> 2.084566
A11: 0.3 | B11: =Engine!$C$62*(1+$A11) -> 1.992715 | C11: =B11*Engine!$C$31 -> 192245.78 | D11: =C11-Engine!$C$60 -> 44364.411 | E11: =IFERROR(D11/C11,0) -> 0.23076923 | F11: =Engine!$D$62*(1+$A11) -> 2.1679486 | G11: =F11*Engine!$D$31 -> 171029.47 | H11: =G11-Engine!$D$60 -> 39468.339 | I11: =IFERROR(H11/G11,0) -> 0.23076923 | K11: =A11 -> 0.3 | L11: =B11 -> 1.992715 | M11: =F11 -> 2.1679486
A12: 0.35 | B12: =Engine!$C$62*(1+$A12) -> 2.0693579 | C12: =B12*Engine!$C$31 -> 199639.85 | D12: =C12-Engine!$C$60 -> 51758.48 | E12: =IFERROR(D12/C12,0) -> 0.25925926 | F12: =Engine!$D$62*(1+$A12) -> 2.2513313 | G12: =F12*Engine!$D$31 -> 177607.53 | H12: =G12-Engine!$D$60 -> 46046.395 | I12: =IFERROR(H12/G12,0) -> 0.25925926 | K12: =A12 -> 0.35 | L12: =B12 -> 2.0693579 | M12: =F12 -> 2.2513313
A13: 0.4 | B13: =Engine!$C$62*(1+$A13) -> 2.1460007 | C13: =B13*Engine!$C$31 -> 207033.92 | D13: =C13-Engine!$C$60 -> 59152.549 | E13: =IFERROR(D13/C13,0) -> 0.28571429 | F13: =Engine!$D$62*(1+$A13) -> 2.3347139 | G13: =F13*Engine!$D$31 -> 184185.58 | H13: =G13-Engine!$D$60 -> 52624.452 | I13: =IFERROR(H13/G13,0) -> 0.28571429 | K13: =A13 -> 0.4 | L13: =B13 -> 2.1460007 | M13: =F13 -> 2.3347139
A15: Selected pricing assumption | C15: Long Distance 40t | D15: Regional 40t
A16: Selected markup over break-even | B16: % | C16: 0.125 | D16: 0.125
A17: Break-even price | B17: EUR/loaded km | C17: =Engine!$C$62 -> 1.5328577 | D17: =Engine!$D$62 -> 1.6676528
A18: Final customer rate per loaded km | B18: EUR/loaded km | C18: =C17*(1+C16) -> 1.7244649 | D18: =D17*(1+D16) -> 1.8761094
A19: Annual revenue at final rate | B19: EUR/year | C19: =C18*Engine!$C$31 -> 166366.54 | D19: =D18*Engine!$D$31 -> 148006.27
A20: EBIT at final rate | B20: EUR/year | C20: =C19-Engine!$C$60 -> 18485.171 | D20: =D19-Engine!$D$60 -> 16445.141
A21: EBIT margin at final rate | B21: % revenue | C21: =IFERROR(C20/C19,0) -> 0.11111111 | D21: =IFERROR(D20/D19,0) -> 0.11111111
A23: Target margin cross-check | C23: Long Distance 40t | D23: Regional 40t
A24: Target EBIT margin from Inputs | B24: % revenue | C24: =Engine!$C$27 -> 0.1 | D24: =Engine!$D$27 -> 0.1
A25: Markup needed to reach target margin | B25: % over break-even | C25: =IFERROR(C24/(1-C24),0) -> 0.11111111 | D25: =IFERROR(D24/(1-D24),0) -> 0.11111111
A26: Rate needed to reach target margin | B26: EUR/loaded km | C26: =Engine!$C$62*(1+C25) -> 1.7031752 | D26: =Engine!$D$62*(1+D25) -> 1.8529476
A28: Logic note
A29: Break-even is calculated first in Engine row 62.
A30: Customer rate is then calculated here as: break-even price × (1 + markup over break-even).
A31: A 10% markup over break-even is not the same as a 10% EBIT margin; a 10% EBIT margin requires an 11.11% markup over break-even.
A33: Tax-adjusted selected pricing view
A35: Metric | B35: Unit | C35: Long Distance 40t | D35: Regional 40t | E35: Formula / source
A36: Customer rate excl. VAT | B36: EUR/loaded km | C36: ='Company & Tax Profile'!C35 -> 1.7244649 | D36: ='Company & Tax Profile'!D35 -> 1.8761094 | E36: From selected pricing assumption above.
A37: Customer invoice rate incl. VAT | B37: EUR/loaded km | C37: ='Company & Tax Profile'!C36 -> 2.0693579 | D37: ='Company & Tax Profile'!D36 -> 2.2513313 | E37: From Company & Tax Profile.
A38: Annual revenue excl. VAT | B38: EUR/year | C38: ='Company & Tax Profile'!C38 -> 166366.54 | D38: 142669.07 | E38: Revenue used for EBIT.
A39: VAT collected / payable | B39: EUR/year | C39: 33752.645 | D39: 29960.505 | E39: Cash/invoice layer only, not revenue.
A40: Invoice value incl. VAT | B40: EUR/year | C40: 194479.53 | D40: 172629.58 | E40: Customer invoice amount incl. VAT.
A41: EBIT before business tax | B41: EUR/year | C41: 17858.542 | D41: 15852.119 | E41: Operational EBIT before company tax.
A42: Business tax charge | B42: EUR/year | C42: 2857.3668 | D42: 2536.3391 | E42: Tax on positive EBIT only.
A43: Profit after business tax | B43: EUR/year | C43: 15001.176 | D43: 13315.78 | E43: EBIT minus business tax.
A44: EBIT margin | B44: % revenue | C44: 0.11111111 | D44: 0.11111111 | E44: EBIT / revenue excl. VAT.
A45: After-tax profit margin | B45: % revenue | C45: 0.093333333 | D45: 0.093333333 | E45: Profit after business tax / revenue excl. VAT.
A46: Required rate for target after-tax margin | B46: EUR/loaded km | C46: 1.6792295 | D46: 1.8228086 | E46: From Company & Tax Profile.

Sheet Sensitivity
A1: Break-even sensitivity
A2: Selected profile | B2: Long Distance 40t | J2: Selected column | K2: =MATCH($B$2,Engine!$C$1:$D$1,0) -> 1
J3: Annual total km | K3: =INDEX(Engine!$C$3:$D$3,1,$K$2) -> 113100
A4: Rate/load factor EBIT matrix | J4: Variable €/total km | K4: =INDEX(Engine!$C$42:$D$42,1,$K$2) -> 0.60441862
A5: Load factor \ Rate | B5: 1.2 | C5: 1.4 | D5: 1.6 | E5: 1.8 | F5: 2 | G5: 2.2 | H5: 2.4 | J5: Fixed incl driver | K5: =INDEX(Engine!$C$57:$D$57,1,$K$2) -> 79521.626
A6: 0.65 | B6: =B$5*$K$3*$A6-($K$5+$K$4*$K$3) -> -59663.371 | C6: =C$5*$K$3*$A6-($K$5+$K$4*$K$3) -> -44960.371 | D6: =D$5*$K$3*$A6-($K$5+$K$4*$K$3) -> -30257.371 | E6: =E$5*$K$3*$A6-($K$5+$K$4*$K$3) -> -15554.371 | F6: =F$5*$K$3*$A6-($K$5+$K$4*$K$3) -> -851.37136 | G6: =G$5*$K$3*$A6-($K$5+$K$4*$K$3) -> 13851.629 | H6: =H$5*$K$3*$A6-($K$5+$K$4*$K$3) -> 28554.629 | J6: Loaded ratio | K6: =INDEX(Engine!$C$8:$D$8,1,$K$2) -> 0.853
A7: 0.7 | B7: =B$5*$K$3*$A7-($K$5+$K$4*$K$3) -> -52877.371 | C7: =C$5*$K$3*$A7-($K$5+$K$4*$K$3) -> -37043.371 | D7: =D$5*$K$3*$A7-($K$5+$K$4*$K$3) -> -21209.371 | E7: =E$5*$K$3*$A7-($K$5+$K$4*$K$3) -> -5375.3714 | F7: =F$5*$K$3*$A7-($K$5+$K$4*$K$3) -> 10458.629 | G7: =G$5*$K$3*$A7-($K$5+$K$4*$K$3) -> 26292.629 | H7: =H$5*$K$3*$A7-($K$5+$K$4*$K$3) -> 42126.629 | J7: Current BE price | K7: =INDEX(Engine!$C$62:$D$62,1,$K$2) -> 1.5328577
A8: 0.75 | B8: =B$5*$K$3*$A8-($K$5+$K$4*$K$3) -> -46091.371 | C8: =C$5*$K$3*$A8-($K$5+$K$4*$K$3) -> -29126.371 | D8: =D$5*$K$3*$A8-($K$5+$K$4*$K$3) -> -12161.371 | E8: =E$5*$K$3*$A8-($K$5+$K$4*$K$3) -> 4803.6286 | F8: =F$5*$K$3*$A8-($K$5+$K$4*$K$3) -> 21768.629 | G8: =G$5*$K$3*$A8-($K$5+$K$4*$K$3) -> 38733.629 | H8: =H$5*$K$3*$A8-($K$5+$K$4*$K$3) -> 55698.629 | J8: Target margin price | K8: =INDEX(Engine!$C$63:$D$63,1,$K$2) -> 1.7031752
A9: 0.8 | B9: =B$5*$K$3*$A9-($K$5+$K$4*$K$3) -> -39305.371 | C9: =C$5*$K$3*$A9-($K$5+$K$4*$K$3) -> -21209.371 | D9: =D$5*$K$3*$A9-($K$5+$K$4*$K$3) -> -3113.3714 | E9: =E$5*$K$3*$A9-($K$5+$K$4*$K$3) -> 14982.629 | F9: =F$5*$K$3*$A9-($K$5+$K$4*$K$3) -> 33078.629 | G9: =G$5*$K$3*$A9-($K$5+$K$4*$K$3) -> 51174.629 | H9: =H$5*$K$3*$A9-($K$5+$K$4*$K$3) -> 69270.629 | J9: Selected customer rate | K9: =INDEX(Engine!$C$28:$D$28,1,$K$2) -> 1.7244649
A10: 0.85 | B10: =B$5*$K$3*$A10-($K$5+$K$4*$K$3) -> -32519.371 | C10: =C$5*$K$3*$A10-($K$5+$K$4*$K$3) -> -13292.371 | D10: =D$5*$K$3*$A10-($K$5+$K$4*$K$3) -> 5934.6286 | E10: =E$5*$K$3*$A10-($K$5+$K$4*$K$3) -> 25161.629 | F10: =F$5*$K$3*$A10-($K$5+$K$4*$K$3) -> 44388.629 | G10: =G$5*$K$3*$A10-($K$5+$K$4*$K$3) -> 63615.629 | H10: =H$5*$K$3*$A10-($K$5+$K$4*$K$3) -> 82842.629 | J10: EBIT at selected rate | K10: =INDEX(Engine!$C$65:$D$65,1,$K$2) -> 18485.171
A11: 0.9 | B11: =B$5*$K$3*$A11-($K$5+$K$4*$K$3) -> -25733.371 | C11: =C$5*$K$3*$A11-($K$5+$K$4*$K$3) -> -5375.3714 | D11: =D$5*$K$3*$A11-($K$5+$K$4*$K$3) -> 14982.629 | E11: =E$5*$K$3*$A11-($K$5+$K$4*$K$3) -> 35340.629 | F11: =F$5*$K$3*$A11-($K$5+$K$4*$K$3) -> 55698.629 | G11: =G$5*$K$3*$A11-($K$5+$K$4*$K$3) -> 76056.629 | H11: =H$5*$K$3*$A11-($K$5+$K$4*$K$3) -> 96414.629
A12: 0.95 | B12: =B$5*$K$3*$A12-($K$5+$K$4*$K$3) -> -18947.371 | C12: =C$5*$K$3*$A12-($K$5+$K$4*$K$3) -> 2541.6286 | D12: =D$5*$K$3*$A12-($K$5+$K$4*$K$3) -> 24030.629 | E12: =E$5*$K$3*$A12-($K$5+$K$4*$K$3) -> 45519.629 | F12: =F$5*$K$3*$A12-($K$5+$K$4*$K$3) -> 67008.629 | G12: =G$5*$K$3*$A12-($K$5+$K$4*$K$3) -> 88497.629 | H12: =H$5*$K$3*$A12-($K$5+$K$4*$K$3) -> 109986.63
A14: Scenario curve at current loaded ratio
A15: Rate | B15: Long Distance EBIT | C15: Regional EBIT
A16: 1.2 | B16: =$A16*Engine!$C$3*Engine!$C$8-(Engine!$C$57+Engine!$C$42*Engine!$C$3) -> -32112.211 | C16: =$A16*Engine!$D$3*Engine!$D$8-(Engine!$D$57+Engine!$D$42*Engine!$D$3) -> -36893.13
A17: 1.3 | B17: =$A17*Engine!$C$3*Engine!$C$8-(Engine!$C$57+Engine!$C$42*Engine!$C$3) -> -22464.781 | C17: =$A17*Engine!$D$3*Engine!$D$8-(Engine!$D$57+Engine!$D$42*Engine!$D$3) -> -29004.13
A18: 1.4 | B18: =$A18*Engine!$C$3*Engine!$C$8-(Engine!$C$57+Engine!$C$42*Engine!$C$3) -> -12817.351 | C18: =$A18*Engine!$D$3*Engine!$D$8-(Engine!$D$57+Engine!$D$42*Engine!$D$3) -> -21115.13
A19: 1.5 | B19: =$A19*Engine!$C$3*Engine!$C$8-(Engine!$C$57+Engine!$C$42*Engine!$C$3) -> -3169.9214 | C19: =$A19*Engine!$D$3*Engine!$D$8-(Engine!$D$57+Engine!$D$42*Engine!$D$3) -> -13226.13
A20: 1.6 | B20: =$A20*Engine!$C$3*Engine!$C$8-(Engine!$C$57+Engine!$C$42*Engine!$C$3) -> 6477.5086 | C20: =$A20*Engine!$D$3*Engine!$D$8-(Engine!$D$57+Engine!$D$42*Engine!$D$3) -> -5337.1299
A21: 1.7 | B21: =$A21*Engine!$C$3*Engine!$C$8-(Engine!$C$57+Engine!$C$42*Engine!$C$3) -> 16124.939 | C21: =$A21*Engine!$D$3*Engine!$D$8-(Engine!$D$57+Engine!$D$42*Engine!$D$3) -> 2551.8701
A22: 1.8 | B22: =$A22*Engine!$C$3*Engine!$C$8-(Engine!$C$57+Engine!$C$42*Engine!$C$3) -> 25772.369 | C22: =$A22*Engine!$D$3*Engine!$D$8-(Engine!$D$57+Engine!$D$42*Engine!$D$3) -> 10440.87
A23: 1.9 | B23: =$A23*Engine!$C$3*Engine!$C$8-(Engine!$C$57+Engine!$C$42*Engine!$C$3) -> 35419.799 | C23: =$A23*Engine!$D$3*Engine!$D$8-(Engine!$D$57+Engine!$D$42*Engine!$D$3) -> 18329.87
A24: 2 | B24: =$A24*Engine!$C$3*Engine!$C$8-(Engine!$C$57+Engine!$C$42*Engine!$C$3) -> 45067.229 | C24: =$A24*Engine!$D$3*Engine!$D$8-(Engine!$D$57+Engine!$D$42*Engine!$D$3) -> 26218.87
A25: 2.1 | B25: =$A25*Engine!$C$3*Engine!$C$8-(Engine!$C$57+Engine!$C$42*Engine!$C$3) -> 54714.659 | C25: =$A25*Engine!$D$3*Engine!$D$8-(Engine!$D$57+Engine!$D$42*Engine!$D$3) -> 34107.87
A26: 2.2 | B26: =$A26*Engine!$C$3*Engine!$C$8-(Engine!$C$57+Engine!$C$42*Engine!$C$3) -> 64362.089 | C26: =$A26*Engine!$D$3*Engine!$D$8-(Engine!$D$57+Engine!$D$42*Engine!$D$3) -> 41996.87
A27: 2.3 | B27: =$A27*Engine!$C$3*Engine!$C$8-(Engine!$C$57+Engine!$C$42*Engine!$C$3) -> 74009.519 | C27: =$A27*Engine!$D$3*Engine!$D$8-(Engine!$D$57+Engine!$D$42*Engine!$D$3) -> 49885.87
A28: 2.4 | B28: =$A28*Engine!$C$3*Engine!$C$8-(Engine!$C$57+Engine!$C$42*Engine!$C$3) -> 83656.949 | C28: =$A28*Engine!$D$3*Engine!$D$8-(Engine!$D$57+Engine!$D$42*Engine!$D$3) -> 57774.87
A31: Load capability sensitivity by vehicle type
A32: This section compares break-even by vehicle capability, from vans to high-capacity trucks. Use EUR/tonne-km when payload is the commercial constraint; use EUR/loaded-km when the truck is sold as a full-truck movement.
A33: Vehicle class | B33: Payload capacity (t) | C33: Effective payload (t) | D33: Loaded km/year | E33: Annual tonne-km | F33: Total annual cost (EUR) | G33: Break-even EUR/loaded km | H33: Break-even EUR/tonne-km | I33: Availability / validation note | J33: Source URL | K33: Data type
A34: ='Vehicle Classes'!A5 -> Small van | B34: ='Vehicle Classes'!D5 -> 1.2 | C34: ='Vehicle Classes'!F5 -> 0.9 | D34: ='Vehicle Classes'!I5 -> 31500 | E34: =D34*C34 -> 28350 | F34: ='Vehicle Classes'!R5 -> 59910.118 | G34: ='Vehicle Classes'!S5 -> 1.9019085 | H34: ='Vehicle Classes'!T5 -> 2.1132317 | I34: ='Vehicle Classes'!U5 -> Model assumption; validate payload against actual van spec | J34: ='Vehicle Classes'!V5 -> https://climate.ec.europa.eu/system/files/2017-03/hdv_lightweighting_en.pdf | K34: ='Vehicle Classes'!W5 -> Editable
A35: ='Vehicle Classes'!A6 -> Large van 3.5t | B35: ='Vehicle Classes'!D6 -> 2 | C35: ='Vehicle Classes'!F6 -> 1.5 | D35: ='Vehicle Classes'!I6 -> 46800 | E35: =D35*C35 -> 70200 | F35: ='Vehicle Classes'!R6 -> 75971.092 | G35: ='Vehicle Classes'!S6 -> 1.6233139 | H35: ='Vehicle Classes'!T6 -> 1.0822093 | I35: ='Vehicle Classes'!U6 -> 3.5t GVW large van; payload can reach about 2t depending on body/spec | J35: ='Vehicle Classes'!V6 -> https://climate.ec.europa.eu/system/files/2017-03/hdv_lightweighting_en.pdf | K35: ='Vehicle Classes'!W6 -> Editable
A36: ='Vehicle Classes'!A7 -> Light truck 7.5t | B36: ='Vehicle Classes'!D7 -> 3.5 | C36: ='Vehicle Classes'!F7 -> 2.8 | D36: ='Vehicle Classes'!I7 -> 56250 | E36: =D36*C36 -> 157500 | F36: 105186.3 | G36: 1.8699786 | H36: 0.6678495 | I36: Operational class assumption; validate by vehicle body and national rules | J36: 0 | K36: Editable
A37: Medium rigid 12t | B37: 6 | C37: 4.92 | D37: 62400 | E37: 307008 | F37: 136873.23 | G37: 2.1934813 | H37: 0.44582953 | I37: Operational class assumption; payload depends on body and axle setup | J37: 0 | K37: Editable
A38: Rigid truck 18t | B38: 9 | C38: 7.65 | D38: 68000 | E38: 520200 | F38: 169093.79 | G38: 2.4866734 | H38: 0.32505534 | I38: Operational class assumption; common distribution/retail class | J38: 0 | K38: Editable
A39: Rigid truck 26t | B39: 14 | C39: 11.9 | D39: 73800 | E39: 878220 | F39: 203308.14 | G39: 2.7548528 | H39: 0.23150024 | I39: Operational class assumption; common 3-axle heavy rigid class | J39: 0 | K39: Editable
A40: Articulated 40t | B40: 24 | C40: 20.832 | D40: 96474.3 | E40: 2009752.6 | F40: 154127.71 | G40: 1.5976038 | H40: 0.076689889 | I40: Standard EU heavy-goods reference class; original model anchor | J40: https://ec.europa.eu/commission/presscorner/detail/en/MEMO_13_329 | K40: Editable
A41: Articulated 44t | B41: 28 | C41: 24.64 | D41: 97266 | E41: 2396634.2 | F41: 178169.45 | G41: 1.8317752 | H41: 0.074341526 | I41: 44t only where rules allow, especially combined/intermodal transport | J41: https://ec.europa.eu/commission/presscorner/detail/en/MEMO_13_329 | K41: Editable
A42: EMS / high-capacity 60t | B42: 38 | C42: 34.2 | D42: 101200 | E42: 3461040 | F42: 226940.9 | G42: 2.242499 | H42: 0.065570146 | I42: Not universal EU-wide; EMS/high-capacity combinations are country/route dependent | J42: https://transport.ec.europa.eu/document/download/45e1073e-373a-4156-966b-0523915dec9f_en?filename=SWD_2023_70_implementation_report_amendments_dir_96_53.pdf | K42: Editable
A45: Payload utilisation matrix - break-even EUR per tonne-km | I45: How to read
...

Sheet Vehicle Classes
A1: Vehicle capability assumptions for break-even sensitivity
A2: Blue numbers are editable assumptions; formula cells calculate effective payload, loaded km, annual cost and break-even price. Validate payload and legal access for actual countries/routes before using commercially.
A4: Vehicle class | B4: Capability band | C4: GVW (t) | D4: Payload capacity (t) | E4: Base payload utilisation | F4: Effective payload (t) | G4: Annual total km | H4: Loaded ratio | I4: Loaded km | J4: Fuel L/100km | K4: Fuel price (EUR/L) | L4: Fuel EUR/km | M4: Non-fuel variable EUR/km | N4: Variable cost annual (EUR) | O4: Driver annual cost (EUR) | P4: Fixed vehicle annual (EUR) | Q4: Structural overhead annual (EUR) | R4: Total annual cost (EUR) | S4: Break-even EUR/loaded km | T4: Break-even EUR/tonne-km | U4: Availability / validation note | V4: Source URL | W4: Input/data type
A5: Small van | B5: Urban / light delivery | C5: 3.5 | D5: 1.2 | E5: 0.75 | F5: =D5*E5 -> 0.9 | G5: 45000 | H5: 0.7 | I5: =G5*H5 -> 31500 | J5: 9.5 | K5: =Inputs!$C$11 -> 1.2655246 | L5: =J5/100*K5 -> 0.12022484 | M5: 0.1 | N5: =(L5+M5)*G5 -> 9910.1178 | O5: 32000 | P5: 12000 | Q5: 6000 | R5: =N5+O5+P5+Q5 -> 59910.118 | S5: =IFERROR(R5/I5,"") -> 1.9019085 | T5: =IFERROR(R5/(I5*F5),"") -> 2.1132317 | U5: Model assumption; validate payload against actual van spec | V5: https://climate.ec.europa.eu/system/files/2017-03/hdv_lightweighting_en.pdf | W5: Editable
A6: Large van 3.5t | B6: Van / courier | C6: 3.5 | D6: 2 | E6: 0.75 | F6: =D6*E6 -> 1.5 | G6: 65000 | H6: 0.72 | I6: =G6*H6 -> 46800 | J6: 12 | K6: =Inputs!$C$11 -> 1.2655246 | L6: =J6/100*K6 -> 0.15186295 | M6: 0.14 | N6: =(L6+M6)*G6 -> 18971.092 | O6: 34000 | P6: 16000 | Q6: 7000 | R6: =N6+O6+P6+Q6 -> 75971.092 | S6: =IFERROR(R6/I6,"") -> 1.6233139 | T6: =IFERROR(R6/(I6*F6),"") -> 1.0822093 | U6: 3.5t GVW large van; payload can reach about 2t depending on body/spec | V6: https://climate.ec.europa.eu/system/files/2017-03/hdv_lightweighting_en.pdf | W6: Editable
A7: Light truck 7.5t | B7: Small rigid | C7: 7.5 | D7: 3.5 | E7: 0.8 | F7: =D7*E7 -> 2.8 | G7: 75000 | H7: 0.75 | I7: =G7*H7 -> 56250 | J7: 16 | K7: =Inputs!$C$11 -> 1.2655246 | L7: =J7/100*K7 -> 0.20248394 | M7: 0.2 | N7: =(L7+M7)*G7 -> 30186.296 | O7: 40000 | P7: 25000 | Q7: 10000 | R7: =N7+O7+P7+Q7 -> 105186.3 | S7: =IFERROR(R7/I7,"") -> 1.8699786 | T7: =IFERROR(R7/(I7*F7),"") -> 0.6678495 | U7: Operational class assumption; validate by vehicle body and national rules | W7: Editable
A8: Medium rigid 12t | B8: Rigid truck | C8: 12 | D8: 6 | E8: 0.82 | F8: =D8*E8 -> 4.92 | G8: 80000 | H8: 0.78 | I8: =G8*H8 -> 62400 | J8: 22 | K8: =Inputs!$C$11 -> 1.2655246 | L8: =J8/100*K8 -> 0.27841542 | M8: 0.27 | N8: =(L8+M8)*G8 -> 43873.233 | O8: 43000 | P8: 38000 | Q8: 12000 | R8: =N8+O8+P8+Q8 -> 136873.23 | S8: =IFERROR(R8/I8,"") -> 2.1934813 | T8: =IFERROR(R8/(I8*F8),"") -> 0.44582953 | U8: Operational class assumption; payload depends on body and axle setup | W8: Editable
A9: Rigid truck 18t | B9: Rigid truck | C9: 18 | D9: 9 | E9: 0.85 | F9: =D9*E9 -> 7.65 | G9: 85000 | H9: 0.8 | I9: =G9*H9 -> 68000 | J9: 27 | K9: =Inputs!$C$11 -> 1.2655246 | L9: =J9/100*K9 -> 0.34169165 | M9: 0.33 | N9: =(L9+M9)*G9 -> 57093.79 | O9: 46000 | P9: 52000 | Q9: 14000 | R9: =N9+O9+P9+Q9 -> 169093.79 | S9: =IFERROR(R9/I9,"") -> 2.4866734 | T9: =IFERROR(R9/(I9*F9),"") -> 0.32505534 | U9: Operational class assumption; common distribution/retail class | W9: Editable
A10: Rigid truck 26t | B10: Heavy rigid | C10: 26 | D10: 14 | E10: 0.85 | F10: =D10*E10 -> 11.9 | G10: 90000 | H10: 0.82 | I10: =G10*H10 -> 73800 | J10: 31 | K10: =Inputs!$C$11 -> 1.2655246 | L10: =J10/100*K10 -> 0.39231263 | M10: 0.4 | N10: =(L10+M10)*G10 -> 71308.137 | O10: 48000 | P10: 68000 | Q10: 16000 | R10: =N10+O10+P10+Q10 -> 203308.14 | S10: =IFERROR(R10/I10,"") -> 2.7548528 | T10: =IFERROR(R10/(I10*F10),"") -> 0.23150024 | U10: Operational class assumption; common 3-axle heavy rigid class | W10: Editable
A11: Articulated 40t | B11: Standard heavy artic | C11: 40 | D11: 24 | E11: 0.868 | F11: =D11*E11 -> 20.832 | G11: 113100 | H11: 0.853 | I11: =G11*H11 -> 96474.3 | J11: 34.2 | K11: =Inputs!$C$11 -> 1.2655246 | L11: =J11/100*K11 -> 0.43280942 | M11: 0.1716 | N11: =(L11+M11)*G11 -> 68358.706 | O11: 49674 | P11: 36095 | Q11: 0 | R11: =N11+O11+P11+Q11 -> 154127.71 | S11: =IFERROR(R11/I11,"") -> 1.5976038 | T11: =IFERROR(R11/(I11*F11),"") -> 0.076689889 | U11: Standard EU heavy-goods reference class; original model anchor | V11: https://ec.europa.eu/commission/presscorner/detail/en/MEMO_13_329 | W11: Editable
A12: Articulated 44t | B12: Intermodal / heavier permitted artic | C12: 44 | D12: 28 | E12: 0.88 | F12: =D12*E12 -> 24.64 | G12: 113100 | H12: 0.86 | I12: =G12*H12 -> 97266 | J12: 35.5 | K12: =Inputs!$C$11 -> 1.2655246 | L12: =J12/100*K12 -> 0.44926124 | M12: 0.18 | N12: =(L12+M12)*G12 -> 71169.446 | O12: 50000 | P12: 39000 | Q12: 18000 | R12: =N12+O12+P12+Q12 -> 178169.45 | S12: =IFERROR(R12/I12,"") -> 1.8317752 | T12: =IFERROR(R12/(I12*F12),"") -> 0.074341526 | U12: 44t only where rules allow, especially combined/intermodal transport | V12: https://ec.europa.eu/commission/presscorner/detail/en/MEMO_13_329 | W12: Editable
A13: EMS / high-capacity 60t | B13: Country/permit dependent EMS | C13: 60 | D13: 38 | E13: 0.9 | F13: =D13*E13 -> 34.2 | G13: 115000 | H13: 0.88 | I13: =G13*H13 -> 101200 | J13: 45 | K13: =Inputs!$C$11 -> 1.2655246 | L13: =J13/100*K13 -> 0.56948608 | M13: 0.23 | N13: =(L13+M13)*G13 -> 91940.899 | O13: 53000 | P13: 60000 | Q13: 22000 | R13: =N13+O13+P13+Q13 -> 226940.9 | S13: =IFERROR(R13/I13,"") -> 2.242499 | T13: =IFERROR(R13/(I13*F13),"") -> 0.065570146 | U13: Not universal EU-wide; EMS/high-capacity combinations are country/route dependent | V13: https://transport.ec.europa.eu/document/download/45e1073e-373a-4156-966b-0523915dec9f_en?filename=SWD_2023_70_implementation_report_amendments_dir_96_53.pdf | W13: Editable
A15: Note: cost values by truck class are modelling placeholders to make the sensitivity engine work. Replace with actual lease/depreciation, insurance, fuel, toll and driver cost data for commercial decisions.

Sheet Tax Rules
A1: Country / jurisdiction
A2: Austria | B2: EUR | C2: Yes | D2: 0.2 | E2: 0.23 | F2: 0 | G2: 0.23 | H2: 0.2098 | I2: 0.1807 | J2: 800 | K2: 0.1 | L2: GmbH | M2: Fleet operator | N2: Corporate rate used for GmbH/AG. Sole traders are subject to progressive personal income tax; validate separately. Vehicle tax is indicative and should be replaced with vehicle-specific Austrian motor/tax data. | O2: https://www.usp.gv.at/en/themen/steuern-finanzen/umsatzsteuer-ueberblick/steuersaetze-und-steuerbefreiungen-der-umsatzsteuer.html | P2: https://www.usp.gv.at/en/themen/steuern-finanzen/koerperschaftsteuer-ueberblick.html | Q2: https://taxsummaries.pwc.com/austria/individual/other-taxes | R2: 2026-05
A3: Germany | B3: EUR | C3: Yes | D3: 0.19 | E3: 0.15825 | F3: 0.14 | G3: 0.29825 | H3: 0.1942 | I3: 0.1933 | J3: 900 | K3: 0.1 | L3: GmbH | M3: Fleet operator | N3: Corporate tax includes 15% Körperschaftsteuer plus 5.5% solidarity surcharge on CIT. Trade tax is municipal; 14% is an average modelling proxy and should be replaced with the exact municipality rate. | O3: https://taxation-customs.ec.europa.eu/taxation/vat/vat-directive/vat-rates_en | P3: https://taxsummaries.pwc.com/germany/corporate/taxes-on-corporate-income | Q3: https://taxsummaries.pwc.com/germany/individual/other-taxes | R3: 2026-05
A4: Romania | B4: RON/EUR | C4: Yes | D4: 0.21 | E4: 0.16 | F4: 0 | G4: 0.16 | H4: 0.0225 | I4: 0.35 | J4: 500 | K4: 0.1 | L4: SRL | M4: Fleet operator | N4: Standard CIT used for SRL/SA. Micro-company turnover tax regimes and special working-condition contributions are not modelled by default. VAT standard rate increased to 21% from 1 August 2025. | O4: https://www.ey.com/en_gl/technical/tax-alerts/romanian-tax-changes-introduced-by-new-fiscal-and-budgetary-measures | P4: https://www.accace.com/tax-guideline-for-romania/ | Q4: https://taxsummaries.pwc.com/romania/individual/other-taxes | R4: 2026-05
A5: Hungary | B5: HUF/EUR | C5: Yes | D5: 0.27 | E5: 0.09 | F5: 0.02 | G5: 0.11 | H5: 0.13 | I5: 0.185 | J5: 500 | K5: 0.1 | L5: Kft. | M5: Fleet operator | N5: Local business tax can be up to 2% and is not an EBIT tax; the model uses it as a simplified profit-tax proxy for pricing sensitivity. Validate with municipality and accountant. | O5: https://taxation-customs.ec.europa.eu/taxation/vat/vat-directive/vat-rates_en | P5: https://taxsummaries.pwc.com/hungary/corporate/taxes-on-corporate-income | Q5: https://taxsummaries.pwc.com/hungary/individual/other-taxes | R5: 2026-05
A6: Bulgaria | B6: BGN/EUR | C6: Yes | D6: 0.2 | E6: 0.1 | F6: 0 | G6: 0.1 | H6: 0.193 | I6: 0.1378 | J6: 400 | K6: 0.1 | L6: EOOD/OOD | M6: Fleet operator | N6: Flat 10% CIT used. Employer contribution uses mid-point of published 2026 range; actual rate depends on activity class and caps. No provincial/local corporate income tax. | O6: https://taxsummaries.pwc.com/bulgaria/corporate/other-taxes | P6: https://taxsummaries.pwc.com/bulgaria/corporate/taxes-on-corporate-income | Q6: https://taxsummaries.pwc.com/bulgaria/individual/other-taxes | R6: 2026-05
A7: Czechia | B7: CZK/EUR | C7: Yes | D7: 0.21 | E7: 0.21 | F7: 0 | G7: 0.21 | H7: 0.338 | I7: 0.116 | J7: 550 | K7: 0.1 | L7: s.r.o. | M7: Fleet operator | N7: Standard corporate rate used for s.r.o./a.s. Employer contribution combines 24.8% social security and 9% health insurance. Vehicle tax is indicative. | O7: https://taxation-customs.ec.europa.eu/taxation/vat/vat-directive/vat-rates_en | P7: https://portal.gov.cz/en/informace/what-is-the-corporate-income-tax-rate-INF-329 | Q7: https://taxsummaries.pwc.com/czech-republic/individual/other-taxes | R7: 2026-05
A8: Slovakia | B8: EUR | C8: Yes | D8: 0.23 | E8: 0.21 | F8: 0 | G8: 0.21 | H8: 0.362 | I8: 0.144 | J8: 550 | K8: 0.1 | L8: s.r.o. | M8: Fleet operator | N8: Default CIT rate assumes taxable income above EUR 100k and up to EUR 5m. 10% micro and 24% high-income bands may apply. Employer contributions total 36.2% in 2026. | O8: https://taxsummaries.pwc.com/slovak-republic/corporate/other-taxes | P8: https://www.accace.com/tax-guideline-for-slovakia/ | Q8: https://taxsummaries.pwc.com/slovak-republic/corporate/other-taxes | R8: 2026-05
A9: Manual / Custom | B9: EUR | C9: No | D9: 0 | E9: 0 | F9: 0 | G9: 0 | H9: 0 | I9: 0 | J9: 0 | K9: 0.1 | L9: Manual entity | M9: Fleet operator | N9: Use this option when the jurisdiction or exact legal entity is not included. Replace all default rates manually before using the model commercially. | O9: Manual input | P9: Manual input | Q9: Manual input | R9: 2026-05

Sheet Dropdown Helper
A1: Country / jurisdiction | B1: Company type 1 | C1: Company type 2 | D1: Company type 3 | E1: Company type 4 | F1: Company type 5 | H1: Business model 1 | I1: Business model 2 | J1: Business model 3 | K1: Business model 4 | L1: Business model 5
A2: Austria | B2: Einzelunternehmen | C2: GmbH | D2: AG | E2: Branch / PE | H2: Owner-operator | I2: Fleet operator | J2: Subcontractor | K2: Mixed | L2: Carrier with subcontractors
A3: Germany | B3: Einzelunternehmen | C3: UG | D3: GmbH | E3: AG | F3: Branch / PE | H3: Owner-operator | I3: Fleet operator | J3: Subcontractor | K3: Mixed | L3: Carrier with subcontractors
A4: Romania | B4: PFA / II | C4: SRL | D4: SA | E4: Branch / PE | H4: Owner-operator | I4: Fleet operator | J4: Subcontractor | K4: Mixed | L4: Carrier with subcontractors
A5: Hungary | B5: Egyéni vállalkozó | C5: Kft. | D5: Zrt. / Nyrt. | E5: Branch / PE | H5: Owner-operator | I5: Fleet operator | J5: Subcontractor | K5: Mixed | L5: Carrier with subcontractors
A6: Bulgaria | B6: ET | C6: EOOD/OOD | D6: AD | E6: Branch / PE | H6: Owner-operator | I6: Fleet operator | J6: Subcontractor | K6: Mixed | L6: Carrier with subcontractors
A7: Czechia | B7: OSVČ | C7: s.r.o. | D7: a.s. | E7: Branch / PE | H7: Owner-operator | I7: Fleet operator | J7: Subcontractor | K7: Mixed | L7: Carrier with subcontractors
A8: Slovakia | B8: živnostník | C8: s.r.o. | D8: a.s. | E8: Branch / PE | H8: Owner-operator | I8: Fleet operator | J8: Subcontractor | K8: Mixed | L8: Carrier with subcontractors
A9: Manual / Custom | B9: Manual entity | H9: Owner-operator | I9: Fleet operator | J9: Subcontractor | K9: Mixed | L9: Carrier with subcontractors

Sheet Cascade Lists
A1: Country / jurisdiction | B1: Company type | C1: Business model | D1: Status
A2: Austria | B2: Einzelunternehmen | C2: Owner-operator | D2: Available
A3: Austria | B3: Einzelunternehmen | C3: Fleet operator | D3: Available
A4: Austria | B4: Einzelunternehmen | C4: Subcontractor | D4: Available
A5: Austria | B5: Einzelunternehmen | C5: Mixed | D5: Available
A6: Austria | B6: Einzelunternehmen | C6: Carrier with subcontractors | D6: Available
A7: Austria | B7: GmbH | C7: Owner-operator | D7: Available
A8: Austria | B8: GmbH | C8: Fleet operator | D8: Available
A9: Austria | B9: GmbH | C9: Subcontractor | D9: Available
A10: Austria | B10: GmbH | C10: Mixed | D10: Available
A11: Austria | B11: GmbH | C11: Carrier with subcontractors | D11: Available
A12: Austria | B12: AG | C12: Owner-operator | D12: Available
... A151: Manual / Custom | B151: Manual entity | C151: Carrier with subcontractors | D151: Available

Sheet Guide
A1: Workbook guide
A2: Use order | B2: Start Here → Company & Tax Profile → Inputs → Engine → Pricing Scenarios → Sensitivity.
A3: Editable cells | B3: Yellow cells are meant for input. Blue cells are formula/linked values. Green cells are key results.
A4: Company & Tax Profile | B4: Country/jurisdiction is the master field. Company type and business model follow it. Tax fields are prefilled from Tax Rules.
A5: Inputs | B5: Daily km is the input; annual total km is calculated as Daily km × Operating days.
A6: Engine | B6: Do not edit. It calculates operational cost, loaded km, break-even €/loaded km and target-margin rates.
A7: Pricing Scenarios | B7: Customer rate is calculated after break-even: break-even × (1 + markup). VAT is shown separately.
A8: Sensitivity | B8: Use to compare rate, load factor, payload utilisation and truck class.
A9: Vehicle Classes | B9: Assumptions for vans, rigid trucks, articulated 40t/44t and EMS/high-capacity 60t scenarios.
A10: Tax Rules | B10: Country defaults for VAT, corporate tax, local/trade tax, payroll contribution and vehicle tax placeholder.
A11: Cascade Lists / Dropdown Helper | B11: Technical support sheets for dropdowns. Modify only if adding new countries or company forms.
A12: Important | B12: Replace default tax and truck-cost assumptions with accountant/tax-advisor and fleet-quote confirmed values before commercial use.
A14: Model logic | B14: Operational break-even is separated from commercial pricing and tax treatment.
... A19: Loaded ratio | B19: Loaded revenue km / annual total km. Empty km still cost money but do not create revenue.
